Workbook

Sheet Sheet1
A1: OID | B1: PlotID | C1: AY | D1: 1.3 | E1: 1.9 | F1: 0.40518 | G1: 0.40837 | H1: 0.41156 | I1: 0.41475 | J1: 0.41794 | K1: 0.42114 | L1: 0.42433 | M1: 0.42752 | N1: 0.43072 | O1: 0.43392 | P1: 0.43711 | Q1: 0.44031 | R1: 0.44351 | S1: 0.4467 | T1: 0.4499 | U1: 0.45309 | V1: 0.45629 | W1: 0.45949 | X1: 0.46268 | Y1: 0.46588 | Z1: 0.46908 | AA1: 0.47227 | AB1: 0.47547 | AC1: 0.47867 | AD1: 0.48184 | AE1: 0.485 | AF1: 0.48816 | AG1: 0.49132 | AH1: 0.49449 | AI1: 0.49765 | AJ1: 0.50081 | AK1: 0.50397 | AL1: 0.50713 | AM1: 0.51029 | AN1: 0.51345 | AO1: 0.51661 | AP1: 0.51978 | AQ1: 0.52306 | AR1: 0.5264 | AS1: 0.52973 | AT1: 0.53306 | AU1: 0.53639 | AV1: 0.53972 | AW1: 0.54305 | AX1: 0.54639 | AY1: 0.54972 | AZ1: 0.55305 | BA1: 0.55638 | BB1: 0.55971 | BC1: 0.56305 | BD1: 0.56638 | BE1: 0.56971 | BF1: 0.57304 | BG1: 0.57638 | BH1: 0.57971 | BI1: 0.58304 | BJ1: 0.58637 | BK1: 0.5896 | BL1: 0.59281 | BM1: 0.59601 | BN1: 0.59922 | BO1: 0.60242 | BP1: 0.60563 | BQ1: 0.60883 | BR1: 0.61204 | BS1: 0.61524 | BT1: 0.61845 | BU1: 0.62165 | BV1: 0.62486 | BW1: 0.62806 | BX1: 0.63126 | BY1: 0.63447 | BZ1: 0.63767 | CA1: 0.64088 | CB1: 0.64408 | CC1: 0.64729 | CD1: 0.65049 | CE1: 0.6537 | CF1: 0.6569 | CG1: 0.66011 | CH1: 0.66331 | CI1: 0.66652 | CJ1: 0.66972 | CK1: 0.67293 | CL1: 0.67613 | CM1: 0.67934 | CN1: 0.68254 | CO1: 0.68575 | CP1: 0.68886 | CQ1: 0.69194 | CR1: 0.69503 | CS1: 0.69811 | CT1: 0.70119 | CU1: 0.70427 | CV1: 0.70735 | CW1: 0.71043 | CX1: 0.71351 | CY1: 0.71659 | CZ1: 0.71967 | DA1: 0.72276 | DB1: 0.72584 | DC1: 0.72892 | DD1: 0.732 | DE1: 0.73508 | DF1: 0.73816 | DG1: 0.74124 | DH1: 0.74432 | DI1: 0.74741 | DJ1: 0.75049 | DK1: 0.75357 | DL1: 0.75665 | DM1: 0.75973 | DN1: 0.76288 | DO1: 0.7661 | DP1: 0.76932 | DQ1: 0.77254 | DR1: 0.77575 | DS1: 0.77897 | DT1: 0.78219 | DU1: 0.78541 | DV1: 0.78863 | DW1: 0.79185 | DX1: 0.79507 | DY1: 0.79829 | DZ1: 0.80151 | EA1: 0.80473 | EB1: 0.80795 | EC1: 0.81116 | ED1: 0.81438 | EE1: 0.81759 | EF1: 0.82077 | EG1: 0.82395 | EH1: 0.82713 | EI1: 0.83031 | EJ1: 0.8335 | EK1: 0.83668 | EL1: 0.83986 | EM1: 0.84304 | EN1: 0.84622 | EO1: 0.8494 | EP1: 0.85258 | EQ1: 0.85576 | ER1: 0.85894 | ES1: 0.86212 | ET1: 0.8653 | EU1: 0.86848 | EV1: 0.87167 | EW1: 0.87485 | EX1: 0.87803 | EY1: 0.88121 | EZ1: 0.88439 | FA1: 0.88757 | FB1: 0.89075 | FC1: 0.89393 | FD1: 0.89711 | FE1: 0.90029 | FF1: 0.90347 | FG1: 0.90666 | FH1: 0.90984 | FI1: 0.91302 | FJ1: 0.9162 | FK1: 0.91938 | FL1: 0.92256 | FM1: 0.92574 | FN1: 0.92892 | FO1: 0.9321 | FP1: 0.93528 | FQ1: 0.93846 | FR1: 0.94165 | FS1: 0.94484 | FT1: 0.94804 | FU1: 0.9506 | FV1: 0.95123 | FW1: 0.95442 | FX1: 0.95605 | FY1: 0.95761 | FZ1: 0.9608 | GA1: 0.96151 | GB1: 0.964 | GC1: 0.96698 | GD1: 0.96719 | GE1: 0.97038 | GF1: 0.97245 | GG1: 0.97357 | GH1: 0.97676 | GI1: 0.97793 | GJ1: 0.97996 | GK1: 0.98315 | GL1: 0.9834 | GM1: 0.98634 | GN1: 0.98887 | GO1: 0.98953 | GP1: 0.99272 | GQ1: 0.99435 | GR1: 0.99592 | GS1: 0.99982 | GT1: 1.00529 | GU1: 1.01076 | GV1: 1.01624 | GW1: 1.02171 | GX1: 1.02719 | GY1: 1.03266 | GZ1: 1.03813 | HA1: 1.04361 | HB1: 1.04908 | HC1: 1.05455 | HD1: 1.06003 | HE1: 1.0655 | HF1: 1.07097 | HG1: 1.07645 | HH1: 1.08192 | HI1: 1.08739 | HJ1: 1.09286 | HK1: 1.09834 | HL1: 1.1038 | HM1: 1.10924 | HN1: 1.11469 | HO1: 1.12014 | HP1: 1.12559 | HQ1: 1.13104 | HR1: 1.13649 | HS1: 1.14194 | HT1: 1.14739 | HU1: 1.15283 | HV1: 1.15828 | HW1: 1.16373 | HX1: 1.16918 | HY1: 1.17463 | HZ1: 1.18008 | IA1: 1.18553 | IB1: 1.19097 | IC1: 1.19641 | ID1: 1.20186 | IE1: 1.20731 | IF1: 1.21276 | IG1: 1.21821 | IH1: 1.22366 | II1: 1.22911 | IJ1: 1.23456 | IK1: 1.24001 | IL1: 1.24545 | IM1: 1.2509 | IN1: 1.25635 | IO1: 1.2618 | IP1: 1.26724 | IQ1: 1.27269 | IR1: 1.27814 | IS1: 1.28358 | IT1: 1.28903 | IU1: 1.50116 | IV1: 1.50657 | IW1: 1.51197 | IX1: 1.51738 | IY1: 1.52278 | IZ1: 1.52819 | JA1: 1.53359 | JB1: 1.539 | JC1: 1.5444 | JD1: 1.5498 | JE1: 1.55521 | JF1: 1.56062 | JG1: 1.56602 | JH1: 1.57143 | JI1: 1.57683 | JJ1: 1.58224 | JK1: 1.5877 | JL1: 1.59317 | JM1: 1.59865 | JN1: 1.60412 | JO1: 1.6096 | JP1: 1.61507 | JQ1: 1.62055 | JR1: 1.62603 | JS1: 1.63149 | JT1: 1.63698 | JU1: 1.64244 | JV1: 1.64793 | JW1: 1.65339 | JX1: 1.65887 | JY1: 1.66435 | JZ1: 1.66982 | KA1: 1.6753 | KB1: 1.68077 | KC1: 1.68625 | KD1: 1.69172 | KE1: 1.6972 | KF1: 1.70268 | KG1: 1.70815 | KH1: 1.71363 | KI1: 1.7191 | KJ1: 1.72458 | KK1: 1.73005 | KL1: 1.73553 | KM1: 1.741 | KN1: 1.74648 | KO1: 1.75195 | KP1: 1.75742 | KQ1: 1.7629 | KR1: 1.76837 | KS1: 1.77385 | KT1: 1.77933 | KU1: 1.7848 | KV1: 1.79028 | KW1: 1.79575 | KX1: 1.80123 | KY1: 1.8067 | KZ1: 1.81218 | LA1: 1.81766 | LB1: 1.82313 | LC1: 1.99286 | LD1: 1.99833 | LE1: 2.00379 | LF1: 2.00918 | LG1: 2.01457 | LH1: 2.01996 | LI1: 2.02536 | LJ1: 2.03075 | LK1: 2.03614 | LL1: 2.04153 | LM1: 2.04692 | LN1: 2.05231 | LO1: 2.05773 | LP1: 2.0632 | LQ1: 2.06868 | LR1: 2.07415 | LS1: 2.07962 | LT1: 2.08508 | LU1: 2.09056 | LV1: 2.09603 | LW1: 2.1015 | LX1: 2.10697 | LY1: 2.11245 | LZ1: 2.11792 | MA1: 2.12339 | MB1: 2.12886 | MC1: 2.13434 | MD1: 2.13981 | ME1: 2.14528 | MF1: 2.15075 | MG1: 2.15623 | MH1: 2.1617 | MI1: 2.16717 | MJ1: 2.17264 | MK1: 2.17812 | ML1: 2.18358 | MM1: 2.18905 | MN1: 2.19453 | MO1: 2.2 | MP1: 2.20545 | MQ1: 2.2109 | MR1: 2.21636 | MS1: 2.22181 | MT1: 2.22727 | MU1: 2.23273 | MV1: 2.23818 | MW1: 2.24364 | MX1: 2.24909 | MY1: 2.25455 | MZ1: 2.26 | NA1: 2.26546 | NB1: 2.27091 | NC1: 2.27637 | ND1: 2.28182 | NE1: 2.28728 | NF1: 2.29273 | NG1: 2.29819 | NH1: 2.30364 | NI1: 2.30909 | NJ1: 2.31455 | NK1: 2.32001 | NL1: 2.32547 | NM1: 2.33094 | NN1: 2.3364 | NO1: 2.34186 | NP1: 2.34732 | NQ1: 2.35279 | NR1: 2.35825 | NS1: 2.36371 | NT1: 2.36917 | NU1: 2.37464 | NV1: 2.3801 | NW1: 2.38556 | NX1: 2.39102 | NY1: 2.39649
A2: 0 | B2: H-102 | C2: NEG | F2: =AVERAGE('2'!C2,'3'!C2,'5'!C2) -> 1.1543779 | G2: =AVERAGE('2'!D2,'3'!D2,'5'!D2) -> 1.2292277 | H2: =AVERAGE('2'!E2,'3'!E2,'5'!E2) -> 1.2968377 | I2: =AVERAGE('2'!F2,'3'!F2,'5'!F2) -> 1.3572078 | J2: =AVERAGE('2'!G2,'3'!G2,'5'!G2) -> 1.4103381 | K2: =AVERAGE('2'!H2,'3'!H2,'5'!H2) -> 1.4562287 | L2: =AVERAGE('2'!I2,'3'!I2,'5'!I2) -> 1.4774055 | M2: =AVERAGE('2'!J2,'3'!J2,'5'!J2) -> 1.5035711 | ... NY2: =AVERAGE('2'!NV2,'3'!NV2,'5'!NV2) -> 7.3850101
A3: 1 | B3: H-115 | C3: NEG | F3: =AVERAGE('2'!C3,'3'!C3,'5'!C3) -> 1.2208707 | G3: =AVERAGE('2'!D3,'3'!D3,'5'!D3) -> 1.2924396 | H3: =AVERAGE('2'!E3,'3'!E3,'5'!E3) -> 1.3581071 | I3: =AVERAGE('2'!F3,'3'!F3,'5'!F3) -> 1.417873 | J3: =AVERAGE('2'!G3,'3'!G3,'5'!G3) -> 1.4717375 | K3: =AVERAGE('2'!H3,'3'!H3,'5'!H3) -> 1.5197005 | L3: =AVERAGE('2'!I3,'3'!I3,'5'!I3) -> 1.5476851 | M3: =AVERAGE('2'!J3,'3'!J3,'5'!J3) -> 1.5775943 | ... NY3: =AVERAGE('2'!NV3,'3'!NV3,'5'!NV3) -> 7.4670277
A4: 2 | B4: H-207 | C4: NEG | F4: =AVERAGE('2'!C4,'3'!C4,'5'!C4) -> 1.2057202 | G4: =AVERAGE('2'!D4,'3'!D4,'5'!D4) -> 1.2693672 | H4: =AVERAGE('2'!E4,'3'!E4,'5'!E4) -> 1.3275519 | I4: =AVERAGE('2'!F4,'3'!F4,'5'!F4) -> 1.3802745 | J4: =AVERAGE('2'!G4,'3'!G4,'5'!G4) -> 1.4275348 | K4: =AVERAGE('2'!H4,'3'!H4,'5'!H4) -> 1.4693328 | L4: =AVERAGE('2'!I4,'3'!I4,'5'!I4) -> 1.4929234 | M4: =AVERAGE('2'!J4,'3'!J4,'5'!J4) -> 1.5130666 | ... NY4: =AVERAGE('2'!NV4,'3'!NV4,'5'!NV4) -> 7.3299422
A5: 3 | B5: H-217 | C5: NEG | F5: =AVERAGE('2'!C5,'3'!C5,'5'!C5) -> 1.1757817 | G5: =AVERAGE('2'!D5,'3'!D5,'5'!D5) -> 1.2448729 | H5: =AVERAGE('2'!E5,'3'!E5,'5'!E5) -> 1.3072015 | I5: =AVERAGE('2'!F5,'3'!F5,'5'!F5) -> 1.3627678 | J5: =AVERAGE('2'!G5,'3'!G5,'5'!G5) -> 1.4115718 | K5: =AVERAGE('2'!H5,'3'!H5,'5'!H5) -> 1.4536133 | L5: =AVERAGE('2'!I5,'3'!I5,'5'!I5) -> 1.4713497 | M5: =AVERAGE('2'!J5,'3'!J5,'5'!J5) -> 1.4929461 | ... NY5: =AVERAGE('2'!NV5,'3'!NV5,'5'!NV5) -> 7.8698441
A6: 4 | B6: H-306 | C6: NEG | F6: =AVERAGE('2'!C6,'3'!C6,'5'!C6) -> 1.1830877 | G6: =AVERAGE('2'!D6,'3'!D6,'5'!D6) -> 1.2567793 | H6: =AVERAGE('2'!E6,'3'!E6,'5'!E6) -> 1.3231576 | I6: =AVERAGE('2'!F6,'3'!F6,'5'!F6) -> 1.3822222 | J6: =AVERAGE('2'!G6,'3'!G6,'5'!G6) -> 1.4339734 | K6: =AVERAGE('2'!H6,'3'!H6,'5'!H6) -> 1.478411 | L6: =AVERAGE('2'!I6,'3'!I6,'5'!I6) -> 1.4988715 | M6: =AVERAGE('2'!J6,'3'!J6,'5'!J6) -> 1.5213227 | ... NY6: =AVERAGE('2'!NV6,'3'!NV6,'5'!NV6) -> 7.3770869
A7: 5 | B7: H-312 | C7: NEG | F7: =AVERAGE('2'!C7,'3'!C7,'5'!C7) -> 1.1873581 | G7: =AVERAGE('2'!D7,'3'!D7,'5'!D7) -> 1.2577153 | H7: =AVERAGE('2'!E7,'3'!E7,'5'!E7) -> 1.3217116 | I7: =AVERAGE('2'!F7,'3'!F7,'5'!F7) -> 1.379347 | J7: =AVERAGE('2'!G7,'3'!G7,'5'!G7) -> 1.4306216 | K7: =AVERAGE('2'!H7,'3'!H7,'5'!H7) -> 1.4755352 | L7: =AVERAGE('2'!I7,'3'!I7,'5'!I7) -> 1.4985474 | M7: =AVERAGE('2'!J7,'3'!J7,'5'!J7) -> 1.5217241 | ... NY7: =AVERAGE('2'!NV7,'3'!NV7,'5'!NV7) -> 7.8072441
A8: 6 | B8: H-405 | C8: NEG | F8: =AVERAGE('2'!C8,'3'!C8,'5'!C8) -> 1.1668083 | G8: =AVERAGE('2'!D8,'3'!D8,'5'!D8) -> 1.2385772 | H8: =AVERAGE('2'!E8,'3'!E8,'5'!E8) -> 1.3035413 | I8: =AVERAGE('2'!F8,'3'!F8,'5'!F8) -> 1.3617003 | J8: =AVERAGE('2'!G8,'3'!G8,'5'!G8) -> 1.4130544 | K8: =AVERAGE('2'!H8,'3'!H8,'5'!H8) -> 1.4576037 | L8: =AVERAGE('2'!I8,'3'!I8,'5'!I8) -> 1.4796421 | M8: =AVERAGE('2'!J8,'3'!J8,'5'!J8) -> 1.5031454 | ... NY8: =AVERAGE('2'!NV8,'3'!NV8,'5'!NV8) -> 7.5025288
A9: 7 | B9: H-411 | C9: NEG | F9: =AVERAGE('2'!C9,'3'!C9,'5'!C9) -> 1.148489 | G9: =AVERAGE('2'!D9,'3'!D9,'5'!D9) -> 1.2196983 | H9: =AVERAGE('2'!E9,'3'!E9,'5'!E9) -> 1.2839041 | I9: =AVERAGE('2'!F9,'3'!F9,'5'!F9) -> 1.3411067 | J9: =AVERAGE('2'!G9,'3'!G9,'5'!G9) -> 1.391306 | K9: =AVERAGE('2'!H9,'3'!H9,'5'!H9) -> 1.4345021 | L9: =AVERAGE('2'!I9,'3'!I9,'5'!I9) -> 1.4531011 | M9: =AVERAGE('2'!J9,'3'!J9,'5'!J9) -> 1.4731104 | ... NY9: =AVERAGE('2'!NV9,'3'!NV9,'5'!NV9) -> 6.8969558
A10: 8 | B10: H-502 | C10: NEG | F10: =AVERAGE('2'!C10,'3'!C10,'5'!C10) -> 1.132133 | G10: =AVERAGE('2'!D10,'3'!D10,'5'!D10) -> 1.2023252 | H10: =AVERAGE('2'!E10,'3'!E10,'5'!E10) -> 1.265813 | I10: =AVERAGE('2'!F10,'3'!F10,'5'!F10) -> 1.3225968 | J10: =AVERAGE('2'!G10,'3'!G10,'5'!G10) -> 1.3726763 | K10: =AVERAGE('2'!H10,'3'!H10,'5'!H10) -> 1.4160516 | L10: =AVERAGE('2'!I10,'3'!I10,'5'!I10) -> 1.43636 | M10: =AVERAGE('2'!J10,'3'!J10,'5'!J10) -> 1.4595253 | ... NY10: =AVERAGE('2'!NV10,'3'!NV10,'5'!NV10) -> 7.5522907
A11: 9 | B11: H-509 | C11: NEG | F11: =AVERAGE('2'!C11,'3'!C11,'5'!C11) -> 1.1305023 | G11: =AVERAGE('2'!D11,'3'!D11,'5'!D11) -> 1.1917518 | H11: =AVERAGE('2'!E11,'3'!E11,'5'!E11) -> 1.2473939 | I11: =AVERAGE('2'!F11,'3'!F11,'5'!F11) -> 1.2974286 | J11: =AVERAGE('2'!G11,'3'!G11,'5'!G11) -> 1.3418558 | K11: =AVERAGE('2'!H11,'3'!H11,'5'!H11) -> 1.3806754 | L11: =AVERAGE('2'!I11,'3'!I11,'5'!I11) -> 1.3984417 | M11: =AVERAGE('2'!J11,'3'!J11,'5'!J11) -> 1.4181462 | ... NY11: =AVERAGE('2'!NV11,'3'!NV11,'5'!NV11) -> 8.0054224
A12: 10 | B12: L-108 | C12: NEG | F12: =AVERAGE('2'!C12,'3'!C12,'5'!C12) -> 1.7382009 | G12: =AVERAGE('2'!D12,'3'!D12,'5'!D12) -> 1.8495253 | H12: =AVERAGE('2'!E12,'3'!E12,'5'!E12) -> 1.9528862 | I12: =AVERAGE('2'!F12,'3'!F12,'5'!F12) -> 2.0482838 | J12: =AVERAGE('2'!G12,'3'!G12,'5'!G12) -> 2.1357182 | K12: =AVERAGE('2'!H12,'3'!H12,'5'!H12) -> 2.215189 | L12: =AVERAGE('2'!I12,'3'!I12,'5'!I12) -> 2.2661759 | M12: =AVERAGE('2'!J12,'3'!J12,'5'!J12) -> 2.3141344 | ... NY12: =AVERAGE('2'!NV12,'3'!NV12,'5'!NV12) -> 11.887531
A13: 11 | B13: L-111 | C13: NEG | F13: =AVERAGE('2'!C13,'3'!C13,'5'!C13) -> 1.6423577 | G13: =AVERAGE('2'!D13,'3'!D13,'5'!D13) -> 1.7461325 | H13: =AVERAGE('2'!E13,'3'!E13,'5'!E13) -> 1.8424338 | I13: =AVERAGE('2'!F13,'3'!F13,'5'!F13) -> 1.9312614 | J13: =AVERAGE('2'!G13,'3'!G13,'5'!G13) -> 2.0126158 | K13: =AVERAGE('2'!H13,'3'!H13,'5'!H13) -> 2.0864966 | L13: =AVERAGE('2'!I13,'3'!I13,'5'!I13) -> 2.1315872 | M13: =AVERAGE('2'!J13,'3'!J13,'5'!J13) -> 2.1827081 | ... NY13: =AVERAGE('2'!NV13,'3'!NV13,'5'!NV13) -> 10.888921
... A35: 33 | B35: L-511 | C35: POS | F35: =AVERAGE('2'!C35,'3'!C35,'5'!C35) -> 1.243398 | G35: =AVERAGE('2'!D35,'3'!D35,'5'!D35) -> 1.3077439 | H35: =AVERAGE('2'!E35,'3'!E35,'5'!E35) -> 1.3682027 | I35: =AVERAGE('2'!F35,'3'!F35,'5'!F35) -> 1.4247744 | J35: =AVERAGE('2'!G35,'3'!G35,'5'!G35) -> 1.477459 | K35: =AVERAGE('2'!H35,'3'!H35,'5'!H35) -> 1.5262566 | L35: =AVERAGE('2'!I35,'3'!I35,'5'!I35) -> 1.5519567 | M35: =AVERAGE('2'!J35,'3'!J35,'5'!J35) -> 1.5824289 | ... NY35: =AVERAGE('2'!NV35,'3'!NV35,'5'!NV35) -> 8.52781

Sheet 2
B1: PlotID | C1: 0.40518 | D1: 0.40837 | E1: 0.41156 | F1: 0.41475 | G1: 0.41794 | H1: 0.42114 | I1: 0.42433 | J1: 0.42752 | K1: 0.43072 | L1: 0.43392 | M1: 0.43711 | N1: 0.44031 | O1: 0.44351 | P1: 0.4467 | Q1: 0.4499 | R1: 0.45309 | S1: 0.45629 | T1: 0.45949 | U1: 0.46268 | V1: 0.46588 | W1: 0.46908 | X1: 0.47227 | Y1: 0.47547 | Z1: 0.47867 | AA1: 0.48184 | AB1: 0.485 | AC1: 0.48816 | AD1: 0.49132 | AE1: 0.49449 | AF1: 0.49765 | AG1: 0.50081 | AH1: 0.50397 | AI1: 0.50713 | AJ1: 0.51029 | AK1: 0.51345 | AL1: 0.51661 | AM1: 0.51978 | AN1: 0.52306 | AO1: 0.5264 | AP1: 0.52973 | AQ1: 0.53306 | AR1: 0.53639 | AS1: 0.53972 | AT1: 0.54305 | AU1: 0.54639 | AV1: 0.54972 | AW1: 0.55305 | AX1: 0.55638 | AY1: 0.55971 | AZ1: 0.56305 | BA1: 0.56638 | BB1: 0.56971 | BC1: 0.57304 | BD1: 0.57638 | BE1: 0.57971 | BF1: 0.58304 | BG1: 0.58637 | BH1: 0.5896 | BI1: 0.59281 | BJ1: 0.59601 | BK1: 0.59922 | BL1: 0.60242 | BM1: 0.60563 | BN1: 0.60883 | BO1: 0.61204 | BP1: 0.61524 | BQ1: 0.61845 | BR1: 0.62165 | BS1: 0.62486 | BT1: 0.62806 | BU1: 0.63126 | BV1: 0.63447 | BW1: 0.63767 | BX1: 0.64088 | BY1: 0.64408 | BZ1: 0.64729 | CA1: 0.65049 | CB1: 0.6537 | CC1: 0.6569 | CD1: 0.66011 | CE1: 0.66331 | CF1: 0.66652 | CG1: 0.66972 | CH1: 0.67293 | CI1: 0.67613 | CJ1: 0.67934 | CK1: 0.68254 | CL1: 0.68575 | CM1: 0.68886 | CN1: 0.69194 | CO1: 0.69503 | CP1: 0.69811 | CQ1: 0.70119 | CR1: 0.70427 | CS1: 0.70735 | CT1: 0.71043 | CU1: 0.71351 | CV1: 0.71659 | CW1: 0.71967 | CX1: 0.72276 | CY1: 0.72584 | CZ1: 0.72892 | DA1: 0.732 | DB1: 0.73508 | DC1: 0.73816 | DD1: 0.74124 | DE1: 0.74432 | DF1: 0.74741 | DG1: 0.75049 | DH1: 0.75357 | DI1: 0.75665 | DJ1: 0.75973 | DK1: 0.76288 | DL1: 0.7661 | DM1: 0.76932 | DN1: 0.77254 | DO1: 0.77575 | DP1: 0.77897 | DQ1: 0.78219 | DR1: 0.78541 | DS1: 0.78863 | DT1: 0.79185 | DU1: 0.79507 | DV1: 0.79829 | DW1: 0.80151 | DX1: 0.80473 | DY1: 0.80795 | DZ1: 0.81116 | EA1: 0.81438 | EB1: 0.81759 | EC1: 0.82077 | ED1: 0.82395 | EE1: 0.82713 | EF1: 0.83031 | EG1: 0.8335 | EH1: 0.83668 | EI1: 0.83986 | EJ1: 0.84304 | EK1: 0.84622 | EL1: 0.8494 | EM1: 0.85258 | EN1: 0.85576 | EO1: 0.85894 | EP1: 0.86212 | EQ1: 0.8653 | ER1: 0.86848 | ES1: 0.87167 | ET1: 0.87485 | EU1: 0.87803 | EV1: 0.88121 | EW1: 0.88439 | EX1: 0.88757 | EY1: 0.89075 | EZ1: 0.89393 | FA1: 0.89711 | FB1: 0.90029 | FC1: 0.90347 | FD1: 0.90666 | FE1: 0.90984 | FF1: 0.91302 | FG1: 0.9162 | FH1: 0.91938 | FI1: 0.92256 | FJ1: 0.92574 | FK1: 0.92892 | FL1: 0.9321 | FM1: 0.93528 | FN1: 0.93846 | FO1: 0.94165 | FP1: 0.94484 | FQ1: 0.94804 | FR1: 0.9506 | FS1: 0.95123 | FT1: 0.95442 | FU1: 0.95605 | FV1: 0.95761 | FW1: 0.9608 | FX1: 0.96151 | FY1: 0.964 | FZ1: 0.96698 | GA1: 0.96719 | GB1: 0.97038 | GC1: 0.97245 | GD1: 0.97357 | GE1: 0.97676 | GF1: 0.97793 | GG1: 0.97996 | GH1: 0.98315 | GI1: 0.9834 | GJ1: 0.98634 | GK1: 0.98887 | GL1: 0.98953 | GM1: 0.99272 | GN1: 0.99435 | GO1: 0.99592 | GP1: 0.99982 | GQ1: 1.00529 | GR1: 1.01076 | GS1: 1.01624 | GT1: 1.02171 | GU1: 1.02719 | GV1: 1.03266 | GW1: 1.03813 | GX1: 1.04361 | GY1: 1.04908 | GZ1: 1.05455 | HA1: 1.06003 | HB1: 1.0655 | HC1: 1.07097 | HD1: 1.07645 | HE1: 1.08192 | HF1: 1.08739 | HG1: 1.09286 | HH1: 1.09834 | HI1: 1.1038 | HJ1: 1.10924 | HK1: 1.11469 | HL1: 1.12014 | HM1: 1.12559 | HN1: 1.13104 | HO1: 1.13649 | HP1: 1.14194 | HQ1: 1.14739 | HR1: 1.15283 | HS1: 1.15828 | HT1: 1.16373 | HU1: 1.16918 | HV1: 1.17463 | HW1: 1.18008 | HX1: 1.18553 | HY1: 1.19097 | HZ1: 1.19641 | IA1: 1.20186 | IB1: 1.20731 | IC1: 1.21276 | ID1: 1.21821 | IE1: 1.22366 | IF1: 1.22911 | IG1: 1.23456 | IH1: 1.24001 | II1: 1.24545 | IJ1: 1.2509 | IK1: 1.25635 | IL1: 1.2618 | IM1: 1.26724 | IN1: 1.27269 | IO1: 1.27814 | IP1: 1.28358 | IQ1: 1.28903 | IR1: 1.50116 | IS1: 1.50657 | IT1: 1.51197 | IU1: 1.51738 | IV1: 1.52278 | IW1: 1.52819 | IX1: 1.53359 | IY1: 1.539 | IZ1: 1.5444 | JA1: 1.5498 | JB1: 1.55521 | JC1: 1.56062 | JD1: 1.56602 | JE1: 1.57143 | JF1: 1.57683 | JG1: 1.58224 | JH1: 1.5877 | JI1: 1.59317 | JJ1: 1.59865 | JK1: 1.60412 | JL1: 1.6096 | JM1: 1.61507 | JN1: 1.62055 | JO1: 1.62603 | JP1: 1.63149 | JQ1: 1.63698 | JR1: 1.64244 | JS1: 1.64793 | JT1: 1.65339 | JU1: 1.65887 | JV1: 1.66435 | JW1: 1.66982 | JX1: 1.6753 | JY1: 1.68077 | JZ1: 1.68625 | KA1: 1.69172 | KB1: 1.6972 | KC1: 1.70268 | KD1: 1.70815 | KE1: 1.71363 | KF1: 1.7191 | KG1: 1.72458 | KH1: 1.73005 | KI1: 1.73553 | KJ1: 1.741 | KK1: 1.74648 | KL1: 1.75195 | KM1: 1.75742 | KN1: 1.7629 | KO1: 1.76837 | KP1: 1.77385 | KQ1: 1.77933 | KR1: 1.7848 | KS1: 1.79028 | KT1: 1.79575 | KU1: 1.80123 | KV1: 1.8067 | KW1: 1.81218 | KX1: 1.81766 | KY1: 1.82313 | KZ1: 1.99286 | LA1: 1.99833 | LB1: 2.00379 | LC1: 2.00918 | LD1: 2.01457 | LE1: 2.01996 | LF1: 2.02536 | LG1: 2.03075 | LH1: 2.03614 | LI1: 2.04153 | LJ1: 2.04692 | LK1: 2.05231 | LL1: 2.05773 | LM1: 2.0632 | LN1: 2.06868 | LO1: 2.07415 | LP1: 2.07962 | LQ1: 2.08508 | LR1: 2.09056 | LS1: 2.09603 | LT1: 2.1015 | LU1: 2.10697 | LV1: 2.11245 | LW1: 2.11792 | LX1: 2.12339 | LY1: 2.12886 | LZ1: 2.13434 | MA1: 2.13981 | MB1: 2.14528 | MC1: 2.15075 | MD1: 2.15623 | ME1: 2.1617 | MF1: 2.16717 | MG1: 2.17264 | MH1: 2.17812 | MI1: 2.18358 | MJ1: 2.18905 | MK1: 2.19453 | ML1: 2.2 | MM1: 2.20545 | MN1: 2.2109 | MO1: 2.21636 | MP1: 2.22181 | MQ1: 2.22727 | MR1: 2.23273 | MS1: 2.23818 | MT1: 2.24364 | MU1: 2.24909 | MV1: 2.25455 | MW1: 2.26 | MX1: 2.26546 | MY1: 2.27091 | MZ1: 2.27637 | NA1: 2.28182 | NB1: 2.28728 | NC1: 2.29273 | ND1: 2.29819 | NE1: 2.30364 | NF1: 2.30909 | NG1: 2.31455 | NH1: 2.32001 | NI1: 2.32547 | NJ1: 2.33094 | NK1: 2.3364 | NL1: 2.34186 | NM1: 2.34732 | NN1: 2.35279 | NO1: 2.35825 | NP1: 2.36371 | NQ1: 2.36917 | NR1: 2.37464 | NS1: 2.3801 | NT1: 2.38556 | NU1: 2.39102 | NV1: 2.39649
A2: 0 | B2: H-102_NEG | C2: 1.5444355 | D2: 1.5785292 | E2: 1.6094759 | F2: 1.6372752 | G2: 1.6619278 | H2: 1.6834331 | I2: 1.6820355 | J2: 1.6890245 | K2: 1.7209698 | L2: 1.7487486 | M2: 1.778871 | N2: 1.8115326 | O2: 1.8361489 | P2: 1.8680399 | Q2: 1.9054572 | R2: 1.9299105 | S2: 1.9384397 | T2: 1.9441627 | U2: 1.9453517 | V2: 1.9513533 | W2: 1.9710144 | X2: 1.9754327 | Y2: 1.9964504 | Z2: 2.0184959 | AA2: 2.0358353 | AB2: 2.0394925 | AC2: 2.0472685 | AD2: 2.0619466 | AE2: 2.0853176 | AF2: 2.1424995 | AG2: 2.2306109 | AH2: 2.355184 | AI2: 2.5702165 | AJ2: 2.8303408 | AK2: 3.1486428 | AL2: 3.5468661 | AM2: 4.002096 | AN2: 4.4927099 | AO2: 4.9772653 | AP2: 5.4239775 | AQ2: 5.7971894 | AR2: 6.0975812 | AS2: 6.3253972 | AT2: 6.4907895 | AU2: 6.6266783 | AV2: 6.7207311 | AW2: 6.7418704 | AX2: 6.7334584 | AY2: 6.6368865 | AZ2: 6.4595061 | BA2: 6.1905327 | BB2: 5.8452087 | BC2: 5.4890866 | BD2: 5.2213653 | BE2: 4.9758874 | BF2: 4.7494459 | BG2: 4.5544502 | BH2: 4.4201899 | BI2: 4.298793 | BJ2: 4.2071826 | BK2: 4.1109503 | BL2: 4.0235643 | BM2: 3.9445347 | BN2: 3.8789069 | BO2: 3.7754295 | BP2: 3.6707184 | BQ2: 3.5573833 | BR2: 3.4531959 | BS2: 3.3628059 | BT2: 3.3032854 | BU2: 3.2517918 | BV2: 3.2255512 | BW2: 3.1614431 | BX2: 3.0687863 | BY2: 2.9931341 | BZ2: 2.8829578 | CA2: 2.7499137 | CB2: 2.6185599 | CC2: 2.4928988 | CD2: 2.3875068 | CE2: 2.2997027 | CF2: 2.2385068 | CG2: 2.1691386 | CH2: 2.1293057 | CI2: 2.1787594 | CJ2: 2.2048664 | CK2: 2.2443757 | CL2: 2.3378797 | CM2: 2.6042694 | CN2: 3.0694648 | CO2: 3.7928719 | CP2: 4.8214514 | CQ2: 6.0537628 | CR2: 7.8147491 | CS2: 10.168551 | CT2: 12.470835 | CU2: 15.060274 | CV2: 17.901463 | CW2: 20.759224 | CX2: 23.653394 | CY2: 26.634766 | CZ2: 29.569112 | DA2: 32.355155 | DB2: 35.295287 | DC2: 38.106492 | DD2: 40.394613 | DE2: 42.219487 | DF2: 43.929338 | DG2: 45.462953 | DH2: 46.667232 | DI2: 47.5558 | DJ2: 48.140598 | DK2: 48.534916 | DL2: 48.875022 | DM2: 49.050989 | DN2: 49.099462 | DO2: 48.874329 | DP2: 49.065397 | DQ2: 49.403735 | DR2: 49.507016 | DS2: 49.551774 | DT2: 49.567972 | DU2: 49.559652 | DV2: 49.486219 | DW2: 49.492766 | DX2: 49.6444 | DY2: 49.753448 | DZ2: 50.023939 | EA2: 50.287617 | EB2: 50.454483 | EC2: 50.581093 | ED2: 50.602954 | EE2: 50.581409 | EF2: 50.534747 | EG2: 50.604001 | EH2: 50.792298 | EI2: 50.861192 | EJ2: 51.127351 | EK2: 51.293072 | EL2: 51.286302 | EM2: 51.361557 | EN2: 51.512166 | EO2: 51.553716 | EP2: 51.593908 | EQ2: 51.598546 | ER2: 51.670282 | ES2: 51.703671 | ET2: 51.844339 | EU2: 51.875895 | EV2: 51.819074 | EW2: 51.804873 | EX2: 52.069816 | EY2: 52.077623 | EZ2: 52.053749 | FA2: 52.161968 | FB2: 52.291092 | FC2: 52.494713 | FD2: 52.58261 | FE2: 52.608628 | FF2: 52.396692 | FG2: 51.896632 | FH2: 51.747032 | FI2: 52.237245 | FJ2: 53.006656 | FK2: 53.49659 | FL2: 54.113963 | FM2: 54.973709 | FN2: 54.375147 | FO2: 53.618906 | FP2: 53.344808 | FQ2: 50.986121 | FR2: 49.093204 | FS2: 48.94385 | FT2: 47.196191 | FU2: 46.302794 | FV2: 45.386315 | FW2: 45.243099 | FX2: 45.14948 | FY2: 45.072418 | FZ2: 45.873887 | GA2: 45.714713 | GB2: 45.814562 | GC2: 46.553656 | GD2: 46.373718 | GE2: 46.594405 | GF2: 46.45079 | GG2: 46.460337 | GH2: 46.78346 | GI2: 46.690315 | GJ2: 46.736099 | GK2: 47.581158 | GL2: 47.33244 | GM2: 47.327285 | GN2: 47.339691 | GO2: 46.573411 | GP2: 46.611126 | GQ2: 46.437816 | GR2: 47.011882 | GS2: 47.939748 | GT2: 48.197277 | GU2: 48.944963 | GV2: 49.015658 | GW2: 48.920189 | GX2: 48.940599 | GY2: 49.341802 | GZ2: 50.14829 | HA2: 51.134995 | HB2: 51.87608 | HC2: 52.240294 | HD2: 51.999667 | HE2: 51.51892 | HF2: 50.965798 | HG2: 50.666823 | HH2: 50.458111 | HI2: 50.996863 | HJ2: 51.175481 | HK2: 51.377739 | HL2: 50.584323 | HM2: 49.403664 | HN2: 47.78394 | HO2: 45.986972 | HP2: 44.117891 | HQ2: 42.432966 | HR2: 41.124539 | HS2: 40.735652 | HT2: 40.271381 | HU2: 40.251342 | HV2: 39.778067 | HW2: 39.565604 | HX2: 39.262553 | HY2: 38.932088 | HZ2: 38.68792 | IA2: 38.653588 | IB2: 38.904002 | IC2: 39.353191 | ID2: 39.845288 | IE2: 40.288184 | IF2: 40.679998 | IG2: 40.957882 | IH2: 41.037557 | II2: 41.176859 | IJ2: 41.224822 | IK2: 41.260494 | IL2: 41.255063 | IM2: 41.225297 | IN2: 41.165432 | IO2: 41.075471 | IP2: 40.955411 | IQ2: 40.805258 | IR2: 11.17822 | IS2: 11.743746 | IT2: 12.306807 | IU2: 12.867402 | IV2: 13.42553 | IW2: 13.981194 | IX2: 14.570685 | IY2: 15.098469 | IZ2: 15.575795 | JA2: 16.160282 | JB2: 16.618691 | JC2: 17.028517 | JD2: 17.457292 | JE2: 17.823542 | JF2: 18.162759 | JG2: 18.440196 | JH2: 18.892794 | JI2: 19.275828 | JJ2: 19.588109 | JK2: 19.990054 | JL2: 20.313482 | JM2: 20.554127 | JN2: 20.870472 | JO2: 21.116391 | JP2: 21.298645 | JQ2: 21.526566 | JR2: 21.870934 | JS2: 22.096906 | JT2: 22.244273 | JU2: 22.464882 | JV2: 22.596292 | JW2: 22.653454 | JX2: 22.729176 | JY2: 22.679222 | JZ2: 22.575551 | KA2: 22.486971 | KB2: 22.282273 | KC2: 22.059293 | KD2: 21.729922 | KE2: 21.523229 | KF2: 21.263381 | KG2: 21.103537 | KH2: 20.849521 | KI2: 20.583251 | KJ2: 20.293709 | KK2: 20.045286 | KL2: 19.684868 | KM2: 19.452889 | KN2: 19.066575 | KO2: 18.714353 | KP2: 18.288382 | KQ2: 17.973395 | KR2: 17.505158 | KS2: 16.848004 | KT2: 15.841445 | KU2: 14.488885 | KV2: 12.859816 | KW2: 10.954234 | KX2: 8.7721391 | KY2: 6.3135345 | KZ2: 5.5293177 | LA2: 5.7260654 | LB2: 5.9013788 | LC2: 6.0552576 | LD2: 6.1877019 | LE2: 6.2987129 | LF2: 6.1777467 | LG2: 6.1971476 | LH2: 6.4036176 | LI2: 6.5431829 | LJ2: 6.8402222 | LK2: 7.0658177 | LL2: 7.2630049 | LM2: 7.4203583 | LN2: 7.5559396 | LO2: 7.6673359 | LP2: 7.8021984 | LQ2: 7.9794895 | LR2: 8.0924236 | LS2: 8.2672337 | LT2: 8.4520291 | LU2: 8.6425829 | LV2: 8.8366754 | LW2: 9.029391 | LX2: 9.1940372 | LY2: 9.3763619 | LZ2: 9.550784 | MA2: 9.6987155 | MB2: 9.8430026 | MC2: 9.9781951 | MD2: 10.086337 | ME2: 10.20727 | MF2: 10.309225 | MG2: 10.462642 | MH2: 10.690364 | MI2: 10.957254 | MJ2: 11.172436 | MK2: 11.3408 | ML2: 11.451866 | MM2: 11.482569 | MN2: 11.43605 | MO2: 11.356243 | MP2: 11.248851 | MQ2: 11.208761 | MR2: 11.215112 | MS2: 11.194403 | MT2: 11.083565 | MU2: 10.903659 | MV2: 10.71359 | MW2: 10.498762 | MX2: 10.308479 | MY2: 10.115191 | MZ2: 9.9486514 | NA2: 9.7840324 | NB2: 9.5991477 | NC2: 9.4291583 | ND2: 9.2466004 | NE2: 9.0278389 | NF2: 8.8098131 | NG2: 8.6047888 | NH2: 8.4963529 | NI2: 8.3970068 | NJ2: 8.3415896 | NK2: 8.2196672 | NL2: 8.0330245 | NM2: 8.0176681 | NN2: 8.0025273 | NO2: 7.9509877 | NP2: 7.9146094 | NQ2: 7.879505 | NR2: 7.8064933 | NS2: 7.7265366 | NT2: 7.6396355 | NU2: 7.5457893 | NV2: 7.4449988
A3: 1 | B3: H-115_NEG | C3: 1.5760002 | D3: 1.6074854 | E3: 1.6370569 | F3: 1.6647142 | G3: 1.6904577 | H3: 1.7142872 | I3: 1.7166973 | J3: 1.727453 | K3: 1.7672617 | L3: 1.8025022 | M3: 1.8350111 | N3: 1.8703031 | O3: 1.8940649 | P3: 1.9258044 | Q3: 1.9712334 | R3: 1.9921537 | S3: 2.0061429 | T3: 2.012294 | U3: 2.0127685 | V3: 2.0238036 | W3: 2.0483886 | X3: 2.058769 | Y3: 2.0816828 | Z3: 2.1083478 | AA3: 2.13031 | AB3: 2.1355766 | AC3: 2.1478346 | AD3: 2.1647217 | AE3: 2.1880059 | AF3: 2.2496875 | AG3: 2.3428599 | AH3: 2.4718742 | AI3: 2.6970097 | AJ3: 2.9681803 | AK3: 3.2937482 | AL3: 3.6985899 | AM3: 4.1687397 | AN3: 4.672433 | AO3: 5.1747311 | AP3: 5.6355211 | AQ3: 6.0188924 | AR3: 6.3300335 | AS3: 6.5658135 | AT3: 6.7346822 | AU3: 6.8670929 | AV3: 6.9589254 | AW3: 6.980785 | AX3: 6.9797997 | AY3: 6.8956558 | AZ3: 6.7326862 | BA3: 6.4741136 | BB3: 6.1428952 | BC3: 5.7881028 | BD3: 5.51746 | BE3: 5.2649541 | BF3: 5.0264462 | BG3: 4.8225831 | BH3: 4.6897416 | BI3: 4.5658834 | BJ3: 4.4818108 | BK3: 4.3888205 | BL3: 4.3138348 | BM3: 4.2358163 | BN3: 4.1735676 | BO3: 4.0715981 | BP3: 3.9630756 | BQ3: 3.8488095 | BR3: 3.7459201 | BS3: 3.6530989 | BT3: 3.5948224 | BU3: 3.5404358 | BV3: 3.5132396 | BW3: 3.4440785 | BX3: 3.3473646 | BY3: 3.2646152 | BZ3: 3.1412325 | CA3: 2.998352 | CB3: 2.8584838 | CC3: 2.7267401 | CD3: 2.6174881 | CE3: 2.5245525 | CF3: 2.4614298 | CG3: 2.3883029 | CH3: 2.3463295 | CI3: 2.401121 | CJ3: 2.4289161 | CK3: 2.4782241 | CL3: 2.5868932 | CM3: 2.8798003 | CN3: 3.3667134 | CO3: 4.1280015 | CP3: 5.2046342 | CQ3: 6.4903498 | CR3: 8.2816786 | CS3: 10.691663 | CT3: 13.013568 | CU3: 15.571088 | CV3: 18.341697 | CW3: 21.098104 | CX3: 23.801065 | CY3: 26.552044 | CZ3: 29.177052 | DA3: 31.625997 | DB3: 34.192995 | DC3: 36.666327 | DD3: 38.618835 | DE3: 40.059656 | DF3: 41.571667 | DG3: 43.049284 | DH3: 44.186768 | DI3: 44.986043 | DJ3: 45.481746 | DK3: 45.831199 | DL3: 46.080099 | DM3: 46.167822 | DN3: 46.119769 | DO3: 45.757439 | DP3: 45.98116 | DQ3: 46.377971 | DR3: 46.495697 | DS3: 46.536907 | DT3: 46.605306 | DU3: 46.667961 | DV3: 46.642285 | DW3: 46.673455 | DX3: 46.859783 | DY3: 46.96832 | DZ3: 47.228546 | EA3: 47.450285 | EB3: 47.606767 | EC3: 47.718473 | ED3: 47.785906 | EE3: 47.835717 | EF3: 47.876444 | EG3: 47.978768 | EH3: 48.252289 | EI3: 48.315838 | EJ3: 48.595406 | EK3: 48.776753 | EL3: 48.777605 | EM3: 48.825895 | EN3: 49.006371 | EO3: 49.080806 | EP3: 49.16517 | EQ3: 49.190661 | ER3: 49.313333 | ES3: 49.343506 | ET3: 49.543856 | EU3: 49.629176 | EV3: 49.576025 | EW3: 49.566551 | EX3: 49.812605 | EY3: 49.821659 | EZ3: 49.821507 | FA3: 49.961575 | FB3: 50.055474 | FC3: 50.274944 | FD3: 50.416895 | FE3: 50.492451 | FF3: 50.356034 | FG3: 49.803347 | FH3: 49.594421 | FI3: 49.98943 | FJ3: 50.795976 | FK3: 51.191717 | FL3: 51.751783 | FM3: 52.512492 | FN3: 52.096939 | FO3: 51.437347 | FP3: 51.174845 | FQ3: 48.983217 | FR3: 47.324957 | FS3: 47.244662 | FT3: 46.01907 | FU3: 45.220093 | FV3: 44.702429 | FW3: 44.80212 | FX3: 44.89276 | FY3: 44.877085 | FZ3: 45.601043 | GA3: 45.337363 | GB3: 45.392819 | GC3: 46.015359 | GD3: 45.800964 | GE3: 45.936917 | GF3: 45.890326 | GG3: 46.082136 | GH3: 46.398952 | GI3: 46.350924 | GJ3: 46.48255 | GK3: 47.147339 | GL3: 47.007593 | GM3: 47.018297 | GN3: 46.992773 | GO3: 46.479215 | GP3: 46.637445 | GQ3: 46.757338 | GR3: 47.415334 | GS3: 48.303022 | GT3: 48.64202 | GU3: 49.22459 | GV3: 49.25587 | GW3: 49.168157 | GX3: 49.231112 | GY3: 49.702511 | GZ3: 50.547973 | HA3: 51.522413 | HB3: 52.22272 | HC3: 52.524699 | HD3: 52.227164 | HE3: 51.743508 | HF3: 51.226244 | HG3: 50.939547 | HH3: 50.702751 | HI3: 51.269099 | HJ3: 51.331234 | HK3: 51.59052 | HL3: 50.756333 | HM3: 49.657688 | HN3: 48.196349 | HO3: 46.66071 | HP3: 45.016685 | HQ3: 43.537373 | HR3: 42.410866 | HS3: 42.178529 | HT3: 41.674041 | HU3: 41.717715 | HV3: 41.107543 | HW3: 40.851483 | HX3: 40.515484 | HY3: 40.204971 | HZ3: 39.956982 | IA3: 39.983413 | IB3: 40.311423 | IC3: 40.829062 | ID3: 41.34929 | IE3: 41.827812 | IF3: 42.222142 | IG3: 42.468853 | IH3: 42.539577 | II3: 42.661462 | IJ3: 42.685643 | IK3: 42.729088 | IL3: 42.72887 | IM3: 42.712697 | IN3: 42.673699 | IO3: 42.611857 | IP3: 42.527184 | IQ3: 42.419679 | IR3: 12.246163 | IS3: 12.874557 | IT3: 13.495633 | IU3: 14.10939 | IV3: 14.715828 | IW3: 15.31495 | IX3: 15.942157 | IY3: 16.507927 | IZ3: 16.997643 | JA3: 17.611013 | JB3: 18.068295 | JC3: 18.492177 | JD3: 18.932228 | JE3: 19.307043 | JF3: 19.672403 | JG3: 19.942515 | JH3: 20.440087 | JI3: 20.85751 | JJ3: 21.18694 | JK3: 21.615026 | JL3: 21.949181 | JM3: 22.192537 | JN3: 22.521345 | JO3: 22.77632 | JP3: 22.958949 | JQ3: 23.188191 | JR3: 23.566911 | JS3: 23.833916 | JT3: 23.994608 | JU3: 24.238782 | JV3: 24.383069 | JW3: 24.430512 | JX3: 24.522835 | JY3: 24.463504 | JZ3: 24.325574 | KA3: 24.213847 | KB3: 23.979477 | KC3: 23.736082 | KD3: 23.359132 | KE3: 23.137056 | KF3: 22.852069 | KG3: 22.669986 | KH3: 22.413935 | KI3: 22.117596 | KJ3: 21.824907 | KK3: 21.581726 | KL3: 21.20058 | KM3: 20.959435 | KN3: 20.557169 | KO3: 20.194897 | KP3: 19.737867 | KQ3: 19.409336 | KR3: 18.921856 | KS3: 18.212866 | KT3: 17.150174 | KU3: 15.67279 | KV3: 13.881072 | KW3: 11.77502 | KX3: 9.3546343 | KY3: 6.6199154 | KZ3: 6.0264968 | LA3: 6.2344059 | LB3: 6.4226122 | LC3: 6.5911169 | LD3: 6.7399173 | LE3: 6.8690153 | LF3: 6.7641122 | LG3: 6.8127294 | LH3: 7.0833933 | LI3: 7.2439117 | LJ3: 7.509626 | LK3: 7.7321733 | LL3: 7.942108 | LM3: 8.0895644 | LN3: 8.2421205 | LO3: 8.3845517 | LP3: 8.5124763 | LQ3: 8.6966609 | LR3: 8.8294078 | LS3: 8.9896507 | LT3: 9.173339 | LU3: 9.4014854 | LV3: 9.5976343 | LW3: 9.7993911 | LX3: 9.9766869 | LY3: 10.161823 | LZ3: 10.345072 | MA3: 10.488747 | MB3: 10.651813 | MC3: 10.789091 | MD3: 10.915657 | ME3: 11.051316 | MF3: 11.15672 | MG3: 11.315016 | MH3: 11.551638 | MI3: 11.869716 | MJ3: 12.101903 | MK3: 12.281106 | ML3: 12.391007 | MM3: 12.404181 | MN3: 12.354465 | MO3: 12.222696 | MP3: 12.104437 | MQ3: 12.008092 | MR3: 12.025017 | MS3: 12.065782 | MT3: 11.937112 | MU3: 11.72115 | MV3: 11.470486 | MW3: 11.185554 | MX3: 10.958772 | MY3: 10.67551 | MZ3: 10.453408 | NA3: 10.246852 | NB3: 10.047221 | NC3: 9.9282947 | ND3: 9.7268318 | NE3: 9.4747113 | NF3: 9.2678575 | NG3: 9.0902444 | NH3: 8.9819648 | NI3: 8.8379185 | NJ3: 8.7345991 | NK3: 8.6020265 | NL3: 8.384975 | NM3: 8.4015511 | NN3: 8.3767681 | NO3: 8.3431493 | NP3: 8.3370678 | NQ3: 8.3063696 | NR3: 8.2289532 | NS3: 8.1298138 | NT3: 8.0089531 | NU3: 7.8663706 | NV3: 7.7020653
A4: 2 | B4: H-207_NEG | C4: 1.5946479 | D4: 1.6153365 | E4: 1.6357991 | F4: 1.6560359 | G4: 1.6760467 | H4: 1.6958316 | I4: 1.7069476 | J4: 1.7157578 | K4: 1.7471641 | L4: 1.7715935 | M4: 1.8080154 | N4: 1.8438251 | O4: 1.8777549 | P4: 1.908938 | Q4: 1.9481736 | R4: 1.9677823 | S4: 1.985333 | T4: 1.9889984 | U4: 1.9902561 | V4: 1.997866 | W4: 2.0253613 | X4: 2.0354249 | Y4: 2.060812 | Z4: 2.0799822 | AA4: 2.1006955 | AB4: 2.1059171 | AC4: 2.1217326 | AD4: 2.1421544 | AE4: 2.1723482 | AF4: 2.2382147 | AG4: 2.3357046 | AH4: 2.4750532 | AI4: 2.6985614 | AJ4: 2.9598999 | AK4: 3.2841058 | AL4: 3.6851591 | AM4: 4.1432096 | AN4: 4.633538 | AO4: 5.1195689 | AP4: 5.5616034 | AQ4: 5.9305252 | AR4: 6.2325694 | AS4: 6.4522664 | AT4: 6.6160168 | AU4: 6.7590467 | AV4: 6.8603522 | AW4: 6.896236 | AX4: 6.9079095 | AY4: 6.8298613 | AZ4: 6.6650308 | BA4: 6.4105522 | BB4: 6.078771 | BC4: 5.7270682 | BD4: 5.4707736 | BE4: 5.2334067 | BF4: 5.013766 | BG4: 4.8284622 | BH4: 4.7012077 | BI4: 4.582679 | BJ4: 4.4996391 | BK4: 4.4099827 | BL4: 4.3305662 | BM4: 4.2515303 | BN4: 4.1887342 | BO4: 4.0869109 | BP4: 3.9761116 | BQ4: 3.863683 | BR4: 3.7624642 | BS4: 3.6746044 | BT4: 3.6150593 | BU4: 3.5678355 | BV4: 3.540793 | BW4: 3.4728207 | BX4: 3.3794391 | BY4: 3.2979748 | BZ4: 3.1745138 | CA4: 3.0376014 | CB4: 2.8973861 | CC4: 2.7637026 | CD4: 2.6482568 | CE4: 2.5573096 | CF4: 2.4897215 | CG4: 2.4147739 | CH4: 2.3756834 | CI4: 2.4272207 | CJ4: 2.447183 | CK4: 2.4873678 | CL4: 2.5892869 | CM4: 2.8893026 | CN4: 3.3869934 | CO4: 4.166203 | CP4: 5.2643176 | CQ4: 6.5639384 | CR4: 8.3642686 | CS4: 10.754584 | CT4: 13.016206 | CU4: 15.548072 | CV4: 18.257551 | CW4: 20.933891 | CX4: 23.558252 | CY4: 26.219143 | CZ4: 28.788844 | DA4: 31.185472 | DB4: 33.69862 | DC4: 36.133846 | DD4: 38.033237 | DE4: 39.544609 | DF4: 41.024124 | DG4: 42.383218 | DH4: 43.427343 | DI4: 44.201637 | DJ4: 44.701038 | DK4: 45.061099 | DL4: 45.377714 | DM4: 45.551719 | DN4: 45.581066 | DO4: 45.380127 | DP4: 45.601115 | DQ4: 45.968941 | DR4: 46.084603 | DS4: 46.153586 | DT4: 46.178679 | DU4: 46.187702 | DV4: 46.158034 | DW4: 46.166603 | DX4: 46.343246 | DY4: 46.478799 | DZ4: 46.750716 | EA4: 47.048641 | EB4: 47.219896 | EC4: 47.395917 | ED4: 47.457054 | EE4: 47.455841 | EF4: 47.420594 | EG4: 47.50862 | EH4: 47.722368 | EI4: 47.83893 | EJ4: 48.126818 | EK4: 48.310212 | EL4: 48.261175 | EM4: 48.356777 | EN4: 48.514635 | EO4: 48.583434 | EP4: 48.66934 | EQ4: 48.758056 | ER4: 48.875649 | ES4: 49.012966 | ET4: 49.195359 | EU4: 49.255899 | EV4: 49.133958 | EW4: 49.166069 | EX4: 49.469413 | EY4: 49.505966 | EZ4: 49.570874 | FA4: 49.703713 | FB4: 49.804594 | FC4: 50.012881 | FD4: 50.065229 | FE4: 50.071949 | FF4: 49.913607 | FG4: 49.401588 | FH4: 49.335621 | FI4: 49.815959 | FJ4: 50.569273 | FK4: 51.009799 | FL4: 51.615437 | FM4: 52.365339 | FN4: 52.027893 | FO4: 51.546789 | FP4: 51.346224 | FQ4: 49.34142 | FR4: 47.761407 | FS4: 47.487061 | FT4: 45.963381 | FU4: 44.951024 | FV4: 44.250626 | FW4: 44.175502 | FX4: 44.15379 | FY4: 44.27723 | FZ4: 45.035024 | GA4: 44.882425 | GB4: 45.054518 | GC4: 45.601031 | GD4: 45.315626 | GE4: 45.467826 | GF4: 45.422278 | GG4: 45.684901 | GH4: 46.048643 | GI4: 46.019035 | GJ4: 46.20597 | GK4: 46.808538 | GL4: 46.852015 | GM4: 46.872351 | GN4: 46.913821 | GO4: 46.590426 | GP4: 46.824012 | GQ4: 47.203947 | GR4: 47.987266 | GS4: 48.849004 | GT4: 49.319127 | GU4: 49.854174 | GV4: 49.894028 | GW4: 49.769562 | GX4: 49.778984 | GY4: 50.195083 | GZ4: 51.015404 | HA4: 52.017567 | HB4: 52.775281 | HC4: 53.127357 | HD4: 52.864671 | HE4: 52.377279 | HF4: 51.82199 | HG4: 51.531951 | HH4: 51.254049 | HI4: 51.728754 | HJ4: 51.745822 | HK4: 51.889432 | HL4: 51.039104 | HM4: 49.832716 | HN4: 48.234357 | HO4: 46.551461 | HP4: 44.88352 | HQ4: 43.426924 | HR4: 42.298015 | HS4: 42.080121 | HT4: 41.698931 | HU4: 41.810061 | HV4: 41.380949 | HW4: 41.188857 | HX4: 40.873044 | HY4: 40.541339 | HZ4: 40.322703 | IA4: 40.318541 | IB4: 40.616383 | IC4: 41.122464 | ID4: 41.659152 | IE4: 42.140243 | IF4: 42.563239 | IG4: 42.847032 | IH4: 42.911736 | II4: 43.040926 | IJ4: 43.084524 | IK4: 43.121013 | IL4: 43.105177 | IM4: 43.084736 | IN4: 43.041987 | IO4: 42.976926 | IP4: 42.889559 | IQ4: 42.779879 | IR4: 12.282018 | IS4: 12.903095 | IT4: 13.520035 | IU4: 14.132842 | IV4: 14.741513 | IW4: 15.346051 | IX4: 15.981306 | IY4: 16.561224 | IZ4: 17.06587 | JA4: 17.694568 | JB4: 18.169612 | JC4: 18.60223 | JD4: 19.062349 | JE4: 19.43485 | JF4: 19.80845 | JG4: 20.082908 | JH4: 20.58744 | JI4: 21.010058 | JJ4: 21.348079 | JK4: 21.7932 | JL4: 22.116355 | JM4: 22.370464 | JN4: 22.701641 | JO4: 22.940374 | JP4: 23.133924 | JQ4: 23.360909 | JR4: 23.736892 | JS4: 23.995607 | JT4: 24.152767 | JU4: 24.405174 | JV4: 24.536017 | JW4: 24.593135 | JX4: 24.672606 | JY4: 24.592423 | JZ4: 24.451914 | KA4: 24.335052 | KB4: 24.100067 | KC4: 23.863447 | KD4: 23.49262 | KE4: 23.26912 | KF4: 22.98487 | KG4: 22.803669 | KH4: 22.552017 | KI4: 22.2654 | KJ4: 21.960411 | KK4: 21.723317 | KL4: 21.347394 | KM4: 21.102052 | KN4: 20.662096 | KO4: 20.248233 | KP4: 19.749858 | KQ4: 19.385982 | KR4: 18.87586 | KS4: 18.153416 | KT4: 17.052647 | KU4: 15.54781 | KV4: 13.731973 | KW4: 11.605133 | KX4: 9.1672914 | KY4: 6.4184493 | KZ4: 5.7648983 | LA4: 6.0034573 | LB4: 6.2213126 | LC4: 6.4184638 | LD4: 6.5949114 | LE4: 6.7506549 | LF4: 6.7263168 | LG4: 6.8560786 | LH4: 7.0121111 | LI4: 7.2149121 | LJ4: 7.4416664 | LK4: 7.65804 | LL4: 7.8519672 | LM4: 8.0226657 | LN4: 8.1888392 | LO4: 8.3379128 | LP4: 8.4921333 | LQ4: 8.6813204 | LR4: 8.8143048 | LS4: 9.0375387 | LT4: 9.2161243 | LU4: 9.4010404 | LV4: 9.5923548 | LW4: 9.8062771 | LX4: 9.9723959 | LY4: 10.150043 | LZ4: 10.318364 | MA4: 10.472271 | MB4: 10.649843 | MC4: 10.780925 | MD4: 10.883949 | ME4: 11.008529 | MF4: 11.129955 | MG4: 11.299955 | MH4: 11.515567 | MI4: 11.777959 | MJ4: 11.979792 | MK4: 12.168354 | ML4: 12.288384 | MM4: 12.302867 | MN4: 12.260286 | MO4: 12.180728 | MP4: 12.075258 | MQ4: 12.034491 | MR4: 12.06099 | MS4: 12.012465 | MT4: 11.881269 | MU4: 11.679084 | MV4: 11.447725 | MW4: 11.169558 | MX4: 10.886411 | MY4: 10.653366 | MZ4: 10.450499 | NA4: 10.31753 | NB4: 10.163455 | NC4: 9.9692217 | ND4: 9.7975749 | NE4: 9.5753147 | NF4: 9.3652112 | NG4: 9.1389615 | NH4: 8.9191312 | NI4: 8.7567385 | NJ4: 8.6234696 | NK4: 8.4690578 | NL4: 8.2695471 | NM4: 8.1827289 | NN4: 8.2036941 | NO4: 8.1373182 | NP4: 8.1029286 | NQ4: 8.0790242 | NR4: 7.9979136 | NS4: 7.899596 | NT4: 7.7840721 | NU4: 7.6513419 | NV4: 7.5014044
A5: 3 | B5: H-217_NEG | C5: 1.4966694 | D5: 1.5257968 | E5: 1.5521361 | F5: 1.5756878 | G5: 1.5964517 | H5: 1.6144279 | I5: 1.608577 | J5: 1.6118576 | K5: 1.6407965 | L5: 1.6691905 | M5: 1.7011912 | N5: 1.7360391 | O5: 1.7653363 | P5: 1.8022678 | Q5: 1.8407879 | R5: 1.8646847 | S5: 1.8766792 | T5: 1.8820166 | U5: 1.8848758 | V5: 1.8932162 | W5: 1.9142354 | X5: 1.9228161 | Y5: 1.9455012 | Z5: 1.9694256 | AA5: 1.9873045 | AB5: 1.9919798 | AC5: 2.0025982 | AD5: 2.0180608 | AE5: 2.0431848 | AF5: 2.1002478 | AG5: 2.189755 | AH5: 2.3184394 | AI5: 2.5401632 | AJ5: 2.8070458 | AK5: 3.1358116 | AL5: 3.5438415 | AM5: 4.0130506 | AN5: 4.5152451 | AO5: 5.0139644 | AP5: 5.4778179 | AQ5: 5.8677081 | AR5: 6.1851112 | AS5: 6.4282065 | AT5: 6.6048345 | AU5: 6.7519293 | AV5: 6.8482357 | AW5: 6.8698303 | AX5: 6.8606953 | AY5: 6.7623116 | AZ5: 6.5854731 | BA5: 6.3141564 | BB5: 5.9650051 | BC5: 5.6013092 | BD5: 5.3241518 | BE5: 5.0695948 | BF5: 4.8303837 | BG5: 4.6254174 | BH5: 4.4849159 | BI5: 4.3598352 | BJ5: 4.2695646 | BK5: 4.1771507 | BL5: 4.0910227 | BM5: 4.0122204 | BN5: 3.9444184 | BO5: 3.8382421 | BP5: 3.7266635 | BQ5: 3.6044175 | BR5: 3.4926169 | BS5: 3.3946119 | BT5: 3.3302346 | BU5: 3.2749476 | BV5: 3.2428905 | BW5: 3.1743262 | BX5: 3.0760463 | BY5: 2.9938453 | BZ5: 2.8741476 | CA5: 2.734003 | CB5: 2.5963315 | CC5: 2.4647978 | CD5: 2.3569904 | CE5: 2.2673392 | CF5: 2.2068429 | CG5: 2.1384642 | CH5: 2.0952503 | CI5: 2.1410815 | CJ5: 2.1606219 | CK5: 2.1980998 | CL5: 2.2933539 | CM5: 2.5667426 | CN5: 3.0500053 | CO5: 3.8076901 | CP5: 4.8835432 | CQ5: 6.1774664 | CR5: 7.9722942 | CS5: 10.393896 | CT5: 12.719749 | CU5: 15.299347 | CV5: 18.099151 | CW5: 20.894296 | CX5: 23.654398 | CY5: 26.461434 | CZ5: 29.187924 | DA5: 31.74336 | DB5: 34.4265 | DC5: 37.026813 | DD5: 39.086824 | DE5: 40.597729 | DF5: 42.244977 | DG5: 43.835059 | DH5: 44.995468 | DI5: 45.794363 | DJ5: 46.291307 | DK5: 46.607865 | DL5: 46.852775 | DM5: 46.933953 | DN5: 46.858314 | DO5: 46.49308 | DP5: 46.795444 | DQ5: 47.228179 | DR5: 47.33903 | DS5: 47.363781 | DT5: 47.411408 | DU5: 47.456925 | DV5: 47.430552 | DW5: 47.464563 | DX5: 47.656963 | DY5: 47.773061 | DZ5: 48.045494 | EA5: 48.290387 | EB5: 48.44524 | EC5: 48.554833 | ED5: 48.576464 | EE5: 48.574179 | EF5: 48.559913 | EG5: 48.664029 | EH5: 48.918653 | EI5: 49.01558 | EJ5: 49.325184 | EK5: 49.513605 | EL5: 49.518802 | EM5: 49.595647 | EN5: 49.774167 | EO5: 49.85003 | EP5: 49.927633 | EQ5: 49.962554 | ER5: 50.077553 | ES5: 50.134047 | ET5: 50.298031 | EU5: 50.341763 | EV5: 50.280099 | EW5: 50.285106 | EX5: 50.551202 | EY5: 50.543272 | EZ5: 50.51659 | FA5: 50.616941 | FB5: 50.719362 | FC5: 50.902546 | FD5: 50.969502 | FE5: 51.018701 | FF5: 50.852315 | FG5: 50.369489 | FH5: 50.19204 | FI5: 50.691664 | FJ5: 51.412817 | FK5: 51.810581 | FL5: 52.348532 | FM5: 53.181702 | FN5: 52.4874 | FO5: 51.722892 | FP5: 51.462329 | FQ5: 49.203989 | FR5: 47.449466 | FS5: 47.392746 | FT5: 45.879776 | FU5: 45.120914 | FV5: 44.48845 | FW5: 44.551514 | FX5: 44.514559 | FY5: 44.513576 | FZ5: 45.326363 | GA5: 45.187828 | GB5: 45.272253 | GC5: 45.960873 | GD5: 45.828341 | GE5: 46.004605 | GF5: 45.952339 | GG5: 46.020031 | GH5: 46.364322 | GI5: 46.302687 | GJ5: 46.336336 | GK5: 47.197288 | GL5: 46.981995 | GM5: 46.963474 | GN5: 46.957079 | GO5: 46.24521 | GP5: 46.344154 | GQ5: 46.228956 | GR5: 46.792015 | GS5: 47.644711 | GT5: 47.809991 | GU5: 48.484914 | GV5: 48.519834 | GW5: 48.436159 | GX5: 48.505904 | GY5: 48.974862 | GZ5: 49.829534 | HA5: 50.80228 | HB5: 51.485307 | HC5: 51.758144 | HD5: 51.432213 | HE5: 50.923155 | HF5: 50.401109 | HG5: 50.106939 | HH5: 49.854778 | HI5: 50.323938 | HJ5: 50.282249 | HK5: 50.406935 | HL5: 49.495325 | HM5: 48.326671 | HN5: 46.810912 | HO5: 45.248117 | HP5: 43.661481 | HQ5: 42.261458 | HR5: 41.198711 | HS5: 40.973877 | HT5: 40.51187 | HU5: 40.575344 | HV5: 40.029701 | HW5: 39.798581 | HX5: 39.469586 | HY5: 39.160482 | HZ5: 38.945167 | IA5: 38.960326 | IB5: 39.270749 | IC5: 39.77603 | ID5: 40.280832 | IE5: 40.748468 | IF5: 41.141082 | IG5: 41.38946 | IH5: 41.447134 | II5: 41.572064 | IJ5: 41.602042 | IK5: 41.633017 | IL5: 41.646338 | IM5: 41.627941 | IN5: 41.584969 | IO5: 41.517415 | IP5: 41.425287 | IQ5: 41.30858 | IR5: 11.804039 | IS5: 12.407806 | IT5: 13.004445 | IU5: 13.593955 | IV5: 14.176338 | IW5: 14.751591 | IX5: 15.345803 | IY5: 15.893361 | IZ5: 16.368007 | JA5: 16.956624 | JB5: 17.4027 | JC5: 17.81777 | JD5: 18.247373 | JE5: 18.616346 | JF5: 18.96944 | JG5: 19.235172 | JH5: 19.715402 | JI5: 20.121769 | JJ5: 20.441088 | JK5: 20.853493 | JL5: 21.172477 | JM5: 21.41947 | JN5: 21.73195 | JO5: 21.978681 | JP5: 22.158662 | JQ5: 22.378783 | JR5: 22.74707 | JS5: 22.984738 | JT5: 23.136437 | JU5: 23.373626 | JV5: 23.514879 | JW5: 23.570279 | JX5: 23.642704 | JY5: 23.586019 | JZ5: 23.462703 | KA5: 23.365072 | KB5: 23.150182 | KC5: 22.917683 | KD5: 22.570815 | KE5: 22.360471 | KF5: 22.095841 | KG5: 21.917834 | KH5: 21.661486 | KI5: 21.393297 | KJ5: 21.095625 | KK5: 20.858055 | KL5: 20.48978 | KM5: 20.249336 | KN5: 19.838957 | KO5: 19.462095 | KP5: 19.010095 | KQ5: 18.67213 | KR5: 18.194443 | KS5: 17.528901 | KT5: 16.511757 | KU5: 15.14111 | KV5: 13.491605 | KW5: 11.563244 | KX5: 9.3560244 | KY5: 6.869946 | KZ5: 5.9501027 | LA5: 6.166553 | LB5: 6.3624646 | LC5: 6.537839 | LD5: 6.6926761 | LE5: 6.8269752 | LF5: 6.7620015 | LG5: 6.7916891 | LH5: 7.0153893 | LI5: 7.1634844 | LJ5: 7.4384008 | LK5: 7.6520589 | LL5: 7.8414475 | LM5: 7.9990922 | LN5: 8.1318886 | LO5: 8.2478252 | LP5: 8.3987069 | LQ5: 8.580022 | LR5: 8.7195098 | LS5: 8.8926637 | LT5: 9.0792145 | LU5: 9.2807435 | LV5: 9.4754961 | LW5: 9.6613664 | LX5: 9.8129111 | LY5: 9.9888151 | LZ5: 10.168159 | MA5: 10.315497 | MB5: 10.469402 | MC5: 10.607522 | MD5: 10.725991 | ME5: 10.861323 | MF5: 10.976225 | MG5: 11.138866 | MH5: 11.363048 | MI5: 11.640262 | MJ5: 11.863873 | MK5: 12.029267 | ML5: 12.13879 | MM5: 12.156003 | MN5: 12.115789 | MO5: 12.035611 | MP5: 11.933849 | MQ5: 11.886862 | MR5: 11.87962 | MS5: 11.855495 | MT5: 11.742937 | MU5: 11.557558 | MV5: 11.356012 | MW5: 11.127465 | MX5: 10.90749 | MY5: 10.701188 | MZ5: 10.514515 | NA5: 10.319142 | NB5: 10.119188 | NC5: 9.9238204 | ND5: 9.7218551 | NE5: 9.4625174 | NF5: 9.2581422 | NG5: 9.0595156 | NH5: 8.9179673 | NI5: 8.828386 | NJ5: 8.7499719 | NK5: 8.6280447 | NL5: 8.4395359 | NM5: 8.4047459 | NN5: 8.3993467 | NO5: 8.3455362 | NP5: 8.3593392 | NQ5: 8.3521258 | NR5: 8.2916547 | NS5: 8.2182631 | NT5: 8.1319524 | NU5: 8.0327205 | NV5: 7.920568
A6: 4 | B6: H-306_NEG | C6: 1.5528076 | D6: 1.5835909 | E6: 1.6113807 | F6: 1.6361763 | G6: 1.6579783 | H6: 1.6767862 | I6: 1.6730002 | J6: 1.6759177 | K6: 1.7050451 | L6: 1.7315482 | M6: 1.7657403 | N6: 1.7983042 | O6: 1.8232335 | P6: 1.8530372 | Q6: 1.8920715 | R6: 1.9168574 | S6: 1.9275118 | T6: 1.9306497 | U6: 1.9316945 | V6: 1.9401199 | W6: 1.9619799 | X6: 1.9677854 | Y6: 1.9873273 | Z6: 2.0091053 | AA6: 2.0245764 | AB6: 2.0298439 | AC6: 2.0396566 | AD6: 2.053673 | AE6: 2.076793 | AF6: 2.1363346 | AG6: 2.2286959 | AH6: 2.354797 | AI6: 2.5687633 | AJ6: 2.8282617 | AK6: 3.1454024 | AL6: 3.5409918 | AM6: 3.9914186 | AN6: 4.4739585 | AO6: 4.9526483 | AP6: 5.3976145 | AQ6: 5.7685766 | AR6: 6.0665101 | AS6: 6.2932074 | AT6: 6.4605357 | AU6: 6.5984761 | AV6: 6.6916075 | AW6: 6.7127713 | AX6: 6.7077782 | AY6: 6.616705 | AZ6: 6.4449545 | BA6: 6.178262 | BB6: 5.8374101 | BC6: 5.4861746 | BD6: 5.2191389 | BE6: 4.9735174 | BF6: 4.7490621 | BG6: 4.5565955 | BH6: 4.4276844 | BI6: 4.3075924 | BJ6: 4.2195002 | BK6: 4.1234713 | BL6: 4.036456 | BM6: 3.9569113 | BN6: 3.8908411 | BO6: 3.7881453 | BP6: 3.6840137 | BQ6: 3.5722695 | BR6: 3.4703606 | BS6: 3.379739 | BT6: 3.3202651 | BU6: 3.266319 | BV6: 3.2386173 | BW6: 3.1731438 | BX6: 3.0820409 | BY6: 3.0044197 | BZ6: 2.8917003 | CA6: 2.7605764 | CB6: 2.6285157 | CC6: 2.502419 | CD6: 2.3986139 | CE6: 2.3128249 | CF6: 2.2546693 | CG6: 2.1879615 | CH6: 2.1500871 | CI6: 2.1995401 | CJ6: 2.2212388 | CK6: 2.2575419 | CL6: 2.3459519 | CM6: 2.6111678 | CN6: 3.0738111 | CO6: 3.804354 | CP6: 4.8481632 | CQ6: 6.0972254 | CR6: 7.8737777 | CS6: 10.256694 | CT6: 12.579118 | CU6: 15.190857 | CV6: 18.059352 | CW6: 20.950403 | CX6: 23.869871 | CY6: 26.883741 | CZ6: 29.846263 | DA6: 32.658216 | DB6: 35.634433 | DC6: 38.488292 | DD6: 40.810498 | DE6: 42.649049 | DF6: 44.428717 | DG6: 46.008617 | DH6: 47.231568 | DI6: 48.129293 | DJ6: 48.724148 | DK6: 49.128684 | DL6: 49.476872 | DM6: 49.660585 | DN6: 49.720215 | DO6: 49.509474 | DP6: 49.760816 | DQ6: 50.117342 | DR6: 50.249102 | DS6: 50.314332 | DT6: 50.365051 | DU6: 50.373865 | DV6: 50.30397 | DW6: 50.319956 | DX6: 50.492528 | DY6: 50.621739 | DZ6: 50.896115 | EA6: 51.167195 | EB6: 51.362899 | EC6: 51.495872 | ED6: 51.528464 | EE6: 51.507327 | EF6: 51.461877 | EG6: 51.544837 | EH6: 51.743576 | EI6: 51.835184 | EJ6: 52.100696 | EK6: 52.283737 | EL6: 52.270687 | EM6: 52.326381 | EN6: 52.488271 | EO6: 52.534718 | EP6: 52.597125 | EQ6: 52.630367 | ER6: 52.725711 | ES6: 52.78544 | ET6: 52.940901 | EU6: 52.993003 | EV6: 52.930957 | EW6: 52.94186 | EX6: 53.217279 | EY6: 53.224498 | EZ6: 53.255573 | FA6: 53.382343 | FB6: 53.50484 | FC6: 53.710256 | FD6: 53.777968 | FE6: 53.787711 | FF6: 53.550513 | FG6: 52.969999 | FH6: 52.730004 | FI6: 53.307938 | FJ6: 54.182443 | FK6: 54.756058 | FL6: 55.418464 | FM6: 56.320343 | FN6: 55.718678 | FO6: 54.928454 | FP6: 54.532654 | FQ6: 52.015006 | FR6: 50.019433 | FS6: 49.870872 | FT6: 48.119995 | FU6: 47.165693 | FV6: 46.222285 | FW6: 46.105722 | FX6: 45.978018 | FY6: 45.903897 | FZ6: 46.709193 | GA6: 46.511543 | GB6: 46.635279 | GC6: 47.378937 | GD6: 47.180007 | GE6: 47.375005 | GF6: 47.255212 | GG6: 47.379458 | GH6: 47.695158 | GI6: 47.597347 | GJ6: 47.696479 | GK6: 48.485232 | GL6: 48.292432 | GM6: 48.298031 | GN6: 48.323863 | GO6: 47.660445 | GP6: 47.785239 | GQ6: 47.792912 | GR6: 48.450896 | GS6: 49.414222 | GT6: 49.775053 | GU6: 50.522504 | GV6: 50.640883 | GW6: 50.572733 | GX6: 50.631956 | GY6: 51.090757 | GZ6: 51.954173 | HA6: 52.998431 | HB6: 53.76015 | HC6: 54.107001 | HD6: 53.822201 | HE6: 53.273226 | HF6: 52.66496 | HG6: 52.318625 | HH6: 52.040332 | HI6: 52.504417 | HJ6: 52.568924 | HK6: 52.644671 | HL6: 51.691989 | HM6: 50.34939 | HN6: 48.543965 | HO6: 46.609974 | HP6: 44.671782 | HQ6: 42.982048 | HR6: 41.681112 | HS6: 41.33571 | HT6: 40.892008 | HU6: 40.901255 | HV6: 40.440932 | HW6: 40.231674 | HX6: 39.893058 | HY6: 39.544434 | HZ6: 39.288033 | IA6: 39.256373 | IB6: 39.530664 | IC6: 40.012539 | ID6: 40.527947 | IE6: 41.003057 | IF6: 41.427512 | IG6: 41.727571 | IH6: 41.816592 | II6: 41.964769 | IJ6: 42.010062 | IK6: 42.039341 | IL6: 42.034124 | IM6: 41.994461 | IN6: 41.920936 | IO6: 41.813548 | IP6: 41.672298 | IQ6: 41.497188 | IR6: 11.239112 | IS6: 11.812257 | IT6: 12.382078 | IU6: 12.948571 | IV6: 13.511737 | IW6: 14.071577 | IX6: 14.654198 | IY6: 15.185918 | IZ6: 15.667866 | JA6: 16.264408 | JB6: 16.720361 | JC6: 17.143039 | JD6: 17.572143 | JE6: 17.934012 | JF6: 18.282868 | JG6: 18.552814 | JH6: 19.017516 | JI6: 19.408332 | JJ6: 19.722856 | JK6: 20.130163 | JL6: 20.444247 | JM6: 20.690929 | JN6: 20.998774 | JO6: 21.239122 | JP6: 21.422485 | JQ6: 21.649655 | JR6: 22.005508 | JS6: 22.24638 | JT6: 22.392914 | JU6: 22.624378 | JV6: 22.763935 | JW6: 22.822222 | JX6: 22.892828 | JY6: 22.831985 | JZ6: 22.71342 | KA6: 22.612133 | KB6: 22.397519 | KC6: 22.172277 | KD6: 21.834771 | KE6: 21.632303 | KF6: 21.369953 | KG6: 21.201363 | KH6: 20.953276 | KI6: 20.681592 | KJ6: 20.396177 | KK6: 20.1535 | KL6: 19.785448 | KM6: 19.549603 | KN6: 19.160574 | KO6: 18.794744 | KP6: 18.347732 | KQ6: 18.019699 | KR6: 17.537849 | KS6: 16.863315 | KT6: 15.847163 | KU6: 14.472391 | KV6: 12.816148 | KW6: 10.878439 | KX6: 8.6592623 | KY6: 6.1586185 | KZ6: 5.5119393 | LA6: 5.7116599 | LB6: 5.8905063 | LC6: 6.0484798 | LD6: 6.1855804 | LE6: 6.3018068 | LF6: 6.1985066 | LG6: 6.2044821 | LH6: 6.4046058 | LI6: 6.564893 | LJ6: 6.8621176 | LK6: 7.0807296 | LL6: 7.259158 | LM6: 7.4036667 | LN6: 7.5324917 | LO6: 7.6395826 | LP6: 7.7831793 | LQ6: 7.9505527 | LR6: 8.0864632 | LS6: 8.2690023 | LT6: 8.4559237 | LU6: 8.6569931 | LV6: 8.8427586 | LW6: 9.036841 | LX6: 9.2038023 | LY6: 9.3746472 | LZ6: 9.5501607 | MA6: 9.6900201 | MB6: 9.8259719 | MC6: 9.9647986 | MD6: 10.079547 | ME6: 10.206133 | MF6: 10.30521 | MG6: 10.44966 | MH6: 10.681066 | MI6: 10.952899 | MJ6: 11.170349 | MK6: 11.334633 | ML6: 11.453324 | MM6: 11.494464 | MN6: 11.458623 | MO6: 11.381925 | MP6: 11.267813 | MQ6: 11.206146 | MR6: 11.243527 | MS6: 11.253143 | MT6: 11.152251 | MU6: 10.973586 | MV6: 10.789996 | MW6: 10.56664 | MX6: 10.33559 | MY6: 10.101775 | MZ6: 9.9027359 | NA6: 9.734455 | NB6: 9.5660573 | NC6: 9.4225194 | ND6: 9.2423191 | NE6: 9.0012107 | NF6: 8.8186561 | NG6: 8.6429464 | NH6: 8.4779622 | NI6: 8.3557926 | NJ6: 8.2652044 | NK6: 8.1458484 | NL6: 7.9686545 | NM6: 7.96122 | NN6: 7.9589631 | NO6: 7.8735448 | NP6: 7.894241 | NQ6: 7.870372 | NR6: 7.7953424 | NS6: 7.7001269 | NT6: 7.5847249 | NU6: 7.4491355 | NV6: 7.2933596
A7: 5 | B7: H-312_NEG | C7: 1.5636706 | D7: 1.5974906 | E7: 1.6285342 | F7: 1.6568011 | G7: 1.6822912 | H7: 1.7050046 | I7: 1.7069716 | J7: 1.7098779 | K7: 1.7452838 | L7: 1.7778658 | M7: 1.8159734 | N7: 1.8542878 | O7: 1.8848224 | P7: 1.9234604 | Q7: 1.9653347 | R7: 1.991838 | S7: 2.0066018 | T7: 2.0133416 | U7: 2.0178259 | V7: 2.0295297 | W7: 2.0538295 | X7: 2.0617267 | Y7: 2.085576 | Z7: 2.1143857 | AA7: 2.1368373 | AB7: 2.1481077 | AC7: 2.1632713 | AD7: 2.1822441 | AE7: 2.2113279 | AF7: 2.2733039 | AG7: 2.36669 | AH7: 2.4923318 | AI7: 2.7062133 | AJ7: 2.958816 | AK7: 3.2645202 | AL7: 3.6416416 | AM7: 4.0672506 | AN7: 4.5212115 | AO7: 4.9727524 | AP7: 5.3948145 | AQ7: 5.7485712 | AR7: 6.0335364 | AS7: 6.2529417 | AT7: 6.4168492 | AU7: 6.5570521 | AV7: 6.6571371 | AW7: 6.6878948 | AX7: 6.69712 | AY7: 6.6295348 | AZ7: 6.4891262 | BA7: 6.2595332 | BB7: 5.9521711 | BC7: 5.6358357 | BD7: 5.4042895 | BE7: 5.1886115 | BF7: 4.9873668 | BG7: 4.8143082 | BH7: 4.6961217 | BI7: 4.5860377 | BJ7: 4.5028716 | BK7: 4.4138521 | BL7: 4.3338635 | BM7: 4.2620227 | BN7: 4.2027062 | BO7: 4.1086463 | BP7: 4.0136812 | BQ7: 3.9131387 | BR7: 3.8164236 | BS7: 3.7321898 | BT7: 3.6779441 | BU7: 3.629812 | BV7: 3.6115759 | BW7: 3.5502061 | BX7: 3.4604055 | BY7: 3.3927284 | BZ7: 3.2850694 | CA7: 3.1557701 | CB7: 3.0244551 | CC7: 2.8985334 | CD7: 2.7931284 | CE7: 2.7051843 | CF7: 2.6453949 | CG7: 2.5728397 | CH7: 2.5302794 | CI7: 2.5878773 | CJ7: 2.6152456 | CK7: 2.6587697 | CL7: 2.7600574 | CM7: 3.0387262 | CN7: 3.5080169 | CO7: 4.2300336 | CP7: 5.2421908 | CQ7: 6.435603 | CR7: 8.1120048 | CS7: 10.356963 | CT7: 12.489886 | CU7: 14.844429 | CV7: 17.38221 | CW7: 19.884702 | CX7: 22.321827 | CY7: 24.763915 | CZ7: 27.101047 | DA7: 29.25268 | DB7: 31.528712 | DC7: 33.714133 | DD7: 35.414845 | DE7: 36.709572 | DF7: 38.041053 | DG7: 39.284876 | DH7: 40.222373 | DI7: 40.895023 | DJ7: 41.340218 | DK7: 41.651812 | DL7: 41.918172 | DM7: 42.054479 | DN7: 42.080789 | DO7: 41.86031 | DP7: 42.103614 | DQ7: 42.466762 | DR7: 42.580615 | DS7: 42.64443 | DT7: 42.701565 | DU7: 42.740021 | DV7: 42.693461 | DW7: 42.725553 | DX7: 42.879732 | DY7: 42.986999 | DZ7: 43.251977 | EA7: 43.509351 | EB7: 43.686199 | EC7: 43.839502 | ED7: 43.894264 | EE7: 43.911786 | EF7: 43.903129 | EG7: 44.002466 | EH7: 44.191238 | EI7: 44.270768 | EJ7: 44.551193 | EK7: 44.727872 | EL7: 44.742706 | EM7: 44.810988 | EN7: 44.971283 | EO7: 45.049606 | EP7: 45.12593 | EQ7: 45.165308 | ER7: 45.264914 | ES7: 45.321606 | ET7: 45.482296 | EU7: 45.54384 | EV7: 45.505803 | EW7: 45.523876 | EX7: 45.809577 | EY7: 45.863287 | EZ7: 45.868283 | FA7: 46.00638 | FB7: 46.172495 | FC7: 46.428309 | FD7: 46.564328 | FE7: 46.658612 | FF7: 46.53513 | FG7: 46.107547 | FH7: 45.999647 | FI7: 46.55667 | FJ7: 47.299066 | FK7: 47.836664 | FL7: 48.515272 | FM7: 49.439755 | FN7: 49.005386 | FO7: 48.43314 | FP7: 48.209655 | FQ7: 46.114665 | FR7: 44.462559 | FS7: 44.396404 | FT7: 42.911508 | FU7: 42.160637 | FV7: 41.502031 | FW7: 41.523595 | FX7: 41.483087 | FY7: 41.48227 | FZ7: 42.214272 | GA7: 42.054661 | GB7: 42.166665 | GC7: 42.797642 | GD7: 42.615045 | GE7: 42.828836 | GF7: 42.751373 | GG7: 42.855514 | GH7: 43.154043 | GI7: 43.072712 | GJ7: 43.174053 | GK7: 43.897476 | GL7: 43.751822 | GM7: 43.749134 | GN7: 43.778316 | GO7: 43.221684 | GP7: 43.324622 | GQ7: 43.334599 | GR7: 43.909296 | GS7: 44.731105 | GT7: 45.001983 | GU7: 45.601766 | GV7: 45.639022 | GW7: 45.554773 | GX7: 45.592831 | GY7: 46.014535 | GZ7: 46.816839 | HA7: 47.744234 | HB7: 48.425006 | HC7: 48.738532 | HD7: 48.486384 | HE7: 48.022123 | HF7: 47.524052 | HG7: 47.251005 | HH7: 47.0227 | HI7: 47.471967 | HJ7: 47.487902 | HK7: 47.666595 | HL7: 46.902638 | HM7: 45.851354 | HN7: 44.462014 | HO7: 43.019745 | HP7: 41.563868 | HQ7: 40.273082 | HR7: 39.298232 | HS7: 39.104176 | HT7: 38.728104 | HU7: 38.845642 | HV7: 38.387296 | HW7: 38.178507 | HX7: 37.879328 | HY7: 37.584626 | HZ7: 37.377592 | IA7: 37.395669 | IB7: 37.682683 | IC7: 38.160493 | ID7: 38.655614 | IE7: 39.113217 | IF7: 39.507422 | IG7: 39.774327 | IH7: 39.847381 | II7: 39.979948 | IJ7: 40.02771 | IK7: 40.059978 | IL7: 40.061704 | IM7: 40.043557 | IN7: 40.001095 | IO7: 39.93432 | IP7: 39.843232 | IQ7: 39.727829 | IR7: 11.906031 | IS7: 12.487541 | IT7: 13.061919 | IU7: 13.629165 | IV7: 14.189279 | IW7: 14.742262 | IX7: 15.315407 | IY7: 15.835986 | IZ7: 16.289825 | JA7: 16.859327 | JB7: 17.277883 | JC7: 17.666148 | JD7: 18.076014 | JE7: 18.406392 | JF7: 18.74438 | JG7: 18.993624 | JH7: 19.456168 | JI7: 19.843135 | JJ7: 20.149418 | JK7: 20.56079 | JL7: 20.864102 | JM7: 21.102607 | JN7: 21.410254 | JO7: 21.635404 | JP7: 21.815215 | JQ7: 22.022939 | JR7: 22.367083 | JS7: 22.597806 | JT7: 22.733803 | JU7: 22.96338 | JV7: 23.094701 | JW7: 23.145867 | JX7: 23.222036 | JY7: 23.167183 | JZ7: 23.054113 | KA7: 22.9609 | KB7: 22.747061 | KC7: 22.522764 | KD7: 22.176177 | KE7: 21.978435 | KF7: 21.717214 | KG7: 21.549758 | KH7: 21.309362 | KI7: 21.051235 | KJ7: 20.785199 | KK7: 20.570598 | KL7: 20.220738 | KM7: 19.992177 | KN7: 19.600697 | KO7: 19.242328 | KP7: 18.799918 | KQ7: 18.486685 | KR7: 18.028506 | KS7: 17.388041 | KT7: 16.418726 | KU7: 15.084069 | KV7: 13.471175 | KW7: 11.580043 | KX7: 9.4106773 | KY7: 6.9630743 | KZ7: 6.3821766 | LA7: 6.5859709 | LB7: 6.7702005 | LC7: 6.9348642 | LD7: 7.0799612 | LE7: 7.2054929 | LF7: 7.1283358 | LG7: 7.1777344 | LH7: 7.3754128 | LI7: 7.516317 | LJ7: 7.7786449 | LK7: 7.971486 | LL7: 8.1299817 | LM7: 8.27885 | LN7: 8.4018401 | LO7: 8.5179662 | LP7: 8.6555233 | LQ7: 8.8275933 | LR7: 8.950715 | LS7: 9.1107918 | LT7: 9.2850761 | LU7: 9.4708708 | LV7: 9.6429448 | LW7: 9.8290935 | LX7: 9.9751972 | LY7: 10.150242 | LZ7: 10.309861 | MA7: 10.459688 | MB7: 10.596425 | MC7: 10.719878 | MD7: 10.826936 | ME7: 10.947908 | MF7: 11.034902 | MG7: 11.195636 | MH7: 11.414604 | MI7: 11.672364 | MJ7: 11.873882 | MK7: 12.045526 | ML7: 12.143337 | MM7: 12.162486 | MN7: 12.121684 | MO7: 12.038908 | MP7: 11.945479 | MQ7: 11.904385 | MR7: 11.911065 | MS7: 11.912136 | MT7: 11.814763 | MU7: 11.653644 | MV7: 11.463588 | MW7: 11.242103 | MX7: 11.020234 | MY7: 10.791794 | MZ7: 10.593762 | NA7: 10.389978 | NB7: 10.188307 | NC7: 10.030816 | ND7: 9.8253516 | NE7: 9.6061674 | NF7: 9.4020652 | NG7: 9.2357083 | NH7: 9.1041281 | NI7: 9.0078699 | NJ7: 8.9336125 | NK7: 8.8213038 | NL7: 8.6328673 | NM7: 8.6146733 | NN7: 8.5996815 | NO7: 8.5710873 | NP7: 8.57725 | NQ7: 8.5954753 | NR7: 8.5383678 | NS7: 8.4617163 | NT7: 8.3655236 | NU7: 8.2497876 | NV7: 8.114509
