Workbook

Sheet Sheet1
A1: OID | B1: PlotID | C1: AY | D1: 1.3 | E1: 1.9 | F1: 0.40534 | G1: 0.40853 | H1: 0.41173 | I1: 0.41492 | J1: 0.41811 | K1: 0.4213 | L1: 0.42449 | M1: 0.4277 | N1: 0.4309 | O1: 0.43411 | P1: 0.43732 | Q1: 0.44053 | R1: 0.44374 | S1: 0.44695 | T1: 0.45015 | U1: 0.45336 | V1: 0.45657 | W1: 0.45978 | X1: 0.46299 | Y1: 0.46619 | Z1: 0.4694 | AA1: 0.47261 | AB1: 0.47582 | AC1: 0.47903 | AD1: 0.4822 | AE1: 0.48534 | AF1: 0.48848 | AG1: 0.49162 | AH1: 0.49475 | AI1: 0.49789 | AJ1: 0.50103 | AK1: 0.50417 | AL1: 0.50731 | AM1: 0.51045 | AN1: 0.51359 | AO1: 0.51673 | AP1: 0.51986 | AQ1: 0.52307 | AR1: 0.52631 | AS1: 0.52954 | AT1: 0.53277 | AU1: 0.53601 | AV1: 0.53924 | AW1: 0.54247 | AX1: 0.54571 | AY1: 0.54894 | AZ1: 0.55218 | BA1: 0.55541 | BB1: 0.55864 | BC1: 0.56188 | BD1: 0.56511 | BE1: 0.56835 | BF1: 0.57158 | BG1: 0.57481 | BH1: 0.57805 | BI1: 0.58128 | BJ1: 0.58449 | BK1: 0.58766 | BL1: 0.59083 | BM1: 0.59401 | BN1: 0.59718 | BO1: 0.60035 | BP1: 0.60353 | BQ1: 0.6067 | BR1: 0.60987 | BS1: 0.61304 | BT1: 0.61622 | BU1: 0.61939 | BV1: 0.62256 | BW1: 0.62574 | BX1: 0.62891 | BY1: 0.63208 | BZ1: 0.63526 | CA1: 0.63843 | CB1: 0.6416 | CC1: 0.64477 | CD1: 0.64795 | CE1: 0.65112 | CF1: 0.65429 | CG1: 0.65747 | CH1: 0.66064 | CI1: 0.66381 | CJ1: 0.66699 | CK1: 0.67016 | CL1: 0.67333 | CM1: 0.6765 | CN1: 0.67968 | CO1: 0.68287 | CP1: 0.68608 | CQ1: 0.68929 | CR1: 0.6925 | CS1: 0.69571 | CT1: 0.69892 | CU1: 0.70213 | CV1: 0.70534 | CW1: 0.70854 | CX1: 0.71175 | CY1: 0.71496 | CZ1: 0.71817 | DA1: 0.72138 | DB1: 0.72459 | DC1: 0.7278 | DD1: 0.73101 | DE1: 0.73422 | DF1: 0.73743 | DG1: 0.74063 | DH1: 0.74384 | DI1: 0.74705 | DJ1: 0.75026 | DK1: 0.75347 | DL1: 0.75668 | DM1: 0.75989 | DN1: 0.7631 | DO1: 0.7663 | DP1: 0.76951 | DQ1: 0.77271 | DR1: 0.77592 | DS1: 0.77912 | DT1: 0.78233 | DU1: 0.78553 | DV1: 0.78874 | DW1: 0.79194 | DX1: 0.79515 | DY1: 0.79835 | DZ1: 0.80156 | EA1: 0.80476 | EB1: 0.80797 | EC1: 0.81118 | ED1: 0.81438 | EE1: 0.81758 | EF1: 0.82077 | EG1: 0.82396 | EH1: 0.82714 | EI1: 0.83033 | EJ1: 0.83352 | EK1: 0.83671 | EL1: 0.8399 | EM1: 0.84308 | EN1: 0.84627 | EO1: 0.84946 | EP1: 0.85265 | EQ1: 0.85584 | ER1: 0.85903 | ES1: 0.86221 | ET1: 0.8654 | EU1: 0.86859 | EV1: 0.87178 | EW1: 0.87496 | EX1: 0.87815 | EY1: 0.88134 | EZ1: 0.88453 | FA1: 0.88771 | FB1: 0.8909 | FC1: 0.89409 | FD1: 0.89728 | FE1: 0.90047 | FF1: 0.90365 | FG1: 0.90684 | FH1: 0.91003 | FI1: 0.91322 | FJ1: 0.91641 | FK1: 0.91959 | FL1: 0.92278 | FM1: 0.92597 | FN1: 0.92916 | FO1: 0.93235 | FP1: 0.93553 | FQ1: 0.93872 | FR1: 0.94191 | FS1: 0.9451 | FT1: 0.9483 | FU1: 0.95056 | FV1: 0.95149 | FW1: 0.95468 | FX1: 0.95601 | FY1: 0.95787 | FZ1: 0.96106 | GA1: 0.96147 | GB1: 0.96426 | GC1: 0.96692 | GD1: 0.96745 | GE1: 0.97064 | GF1: 0.97237 | GG1: 0.97383 | GH1: 0.97702 | GI1: 0.97782 | GJ1: 0.98022 | GK1: 0.98327 | GL1: 0.98341 | GM1: 0.9866 | GN1: 0.98873 | GO1: 0.98979 | GP1: 0.99298 | GQ1: 0.99418 | GR1: 0.99618 | GS1: 0.99963 | GT1: 1.00508 | GU1: 1.01053 | GV1: 1.01599 | GW1: 1.02144 | GX1: 1.02689 | GY1: 1.03235 | GZ1: 1.0378 | HA1: 1.04325 | HB1: 1.0487 | HC1: 1.05416 | HD1: 1.05961 | HE1: 1.06506 | HF1: 1.07052 | HG1: 1.07597 | HH1: 1.08142 | HI1: 1.08687 | HJ1: 1.09232 | HK1: 1.09777 | HL1: 1.10323 | HM1: 1.1087 | HN1: 1.11416 | HO1: 1.11963 | HP1: 1.1251 | HQ1: 1.13057 | HR1: 1.13603 | HS1: 1.1415 | HT1: 1.14697 | HU1: 1.15243 | HV1: 1.1579 | HW1: 1.16337 | HX1: 1.16884 | HY1: 1.1743 | HZ1: 1.17977 | IA1: 1.18524 | IB1: 1.1907 | IC1: 1.19616 | ID1: 1.20164 | IE1: 1.2071 | IF1: 1.21256 | IG1: 1.21803 | IH1: 1.2235 | II1: 1.22896 | IJ1: 1.23443 | IK1: 1.2399 | IL1: 1.24536 | IM1: 1.25083 | IN1: 1.25628 | IO1: 1.26171 | IP1: 1.26715 | IQ1: 1.27258 | IR1: 1.27801 | IS1: 1.28344 | IT1: 1.28888 | IU1: 1.50086 | IV1: 1.50631 | IW1: 1.51176 | IX1: 1.51722 | IY1: 1.52267 | IZ1: 1.52813 | JA1: 1.53358 | JB1: 1.53902 | JC1: 1.54448 | JD1: 1.54993 | JE1: 1.55538 | JF1: 1.56084 | JG1: 1.56629 | JH1: 1.57174 | JI1: 1.5772 | JJ1: 1.58265 | JK1: 1.58811 | JL1: 1.59358 | JM1: 1.59904 | JN1: 1.60451 | JO1: 1.60998 | JP1: 1.61544 | JQ1: 1.62091 | JR1: 1.62638 | JS1: 1.63183 | JT1: 1.63731 | JU1: 1.64277 | JV1: 1.64823 | JW1: 1.6537 | JX1: 1.65916 | JY1: 1.66463 | JZ1: 1.6701 | KA1: 1.67556 | KB1: 1.68103 | KC1: 1.68649 | KD1: 1.69196 | KE1: 1.69743 | KF1: 1.70289 | KG1: 1.70836 | KH1: 1.71383 | KI1: 1.71929 | KJ1: 1.72476 | KK1: 1.73022 | KL1: 1.73569 | KM1: 1.74116 | KN1: 1.74662 | KO1: 1.75208 | KP1: 1.75756 | KQ1: 1.76301 | KR1: 1.76848 | KS1: 1.77394 | KT1: 1.77941 | KU1: 1.78488 | KV1: 1.79034 | KW1: 1.79581 | KX1: 1.80128 | KY1: 1.80674 | KZ1: 1.81221 | LA1: 1.81767 | LB1: 1.82314 | LC1: 1.99257 | LD1: 1.99804 | LE1: 2.0035 | LF1: 2.00895 | LG1: 2.0144 | LH1: 2.01984 | LI1: 2.02529 | LJ1: 2.03074 | LK1: 2.03618 | LL1: 2.04163 | LM1: 2.04708 | LN1: 2.05252 | LO1: 2.05797 | LP1: 2.0634 | LQ1: 2.06882 | LR1: 2.07425 | LS1: 2.07967 | LT1: 2.0851 | LU1: 2.09053 | LV1: 2.09596 | LW1: 2.10138 | LX1: 2.10681 | LY1: 2.11224 | LZ1: 2.11767 | MA1: 2.1231 | MB1: 2.12853 | MC1: 2.13396 | MD1: 2.13938 | ME1: 2.14481 | MF1: 2.15024 | MG1: 2.15567 | MH1: 2.1611 | MI1: 2.16653 | MJ1: 2.17195 | MK1: 2.17738 | ML1: 2.18281 | MM1: 2.18824 | MN1: 2.19367 | MO1: 2.19912 | MP1: 2.20461 | MQ1: 2.2101 | MR1: 2.21559 | MS1: 2.22109 | MT1: 2.22658 | MU1: 2.23208 | MV1: 2.23757 | MW1: 2.24306 | MX1: 2.24856 | MY1: 2.25405 | MZ1: 2.25955 | NA1: 2.26504 | NB1: 2.27053 | NC1: 2.27603 | ND1: 2.28152 | NE1: 2.28702 | NF1: 2.29251 | NG1: 2.298 | NH1: 2.30349 | NI1: 2.30898 | NJ1: 2.31446 | NK1: 2.3199 | NL1: 2.32534 | NM1: 2.33077 | NN1: 2.33621 | NO1: 2.34165 | NP1: 2.34708 | NQ1: 2.35252 | NR1: 2.35795 | NS1: 2.36339 | NT1: 2.36883 | NU1: 2.37426 | NV1: 2.3797 | NW1: 2.38514 | NX1: 2.39057 | NY1: 2.39601
A2: 0 | B2: H-102 | C2: NEG | F2: =MAX('1'!C2,'2'!C2) -> 0.91266267 | G2: =MAX('1'!D2,'2'!D2) -> 1.025977 | H2: =MAX('1'!E2,'2'!E2) -> 1.1147119 | I2: =MAX('1'!F2,'2'!F2) -> 1.1788673 | J2: =MAX('1'!G2,'2'!G2) -> 1.2184433 | K2: =MAX('1'!H2,'2'!H2) -> 1.23344 | L2: =MAX('1'!I2,'2'!I2) -> 1.1504081 | M2: =MAX('1'!J2,'2'!J2) -> 1.108903 | ... NY2: =MAX('1'!NV2,'2'!NV2) -> 12.232144
A3: 1 | B3: H-115 | C3: NEG | F3: =MAX('1'!C3,'2'!C3) -> 0.94503894 | G3: =MAX('1'!D3,'2'!D3) -> 0.99868976 | H3: =MAX('1'!E3,'2'!E3) -> 1.0529367 | I3: =MAX('1'!F3,'2'!F3) -> 1.10778 | J3: =MAX('1'!G3,'2'!G3) -> 1.1632193 | K3: =MAX('1'!H3,'2'!H3) -> 1.2192549 | L3: =MAX('1'!I3,'2'!I3) -> 1.2601508 | M3: =MAX('1'!J3,'2'!J3) -> 1.3251818 | ... NY3: =MAX('1'!NV3,'2'!NV3) -> 14.158316
A4: 2 | B4: H-207 | C4: NEG | F4: =MAX('1'!C4,'2'!C4) -> 0.80691681 | G4: =MAX('1'!D4,'2'!D4) -> 0.96283107 | H4: =MAX('1'!E4,'2'!E4) -> 1.0872587 | I4: =MAX('1'!F4,'2'!F4) -> 1.1801997 | J4: =MAX('1'!G4,'2'!G4) -> 1.2416539 | K4: =MAX('1'!H4,'2'!H4) -> 1.2716215 | L4: =MAX('1'!I4,'2'!I4) -> 1.1879755 | M4: =MAX('1'!J4,'2'!J4) -> 1.1400947 | ... NY4: =MAX('1'!NV4,'2'!NV4) -> 12.331145
A5: 3 | B5: H-217 | C5: NEG | F5: =MAX('1'!C5,'2'!C5) -> 0.86833597 | G5: =MAX('1'!D5,'2'!D5) -> 0.96000941 | H5: =MAX('1'!E5,'2'!E5) -> 1.0452967 | I5: =MAX('1'!F5,'2'!F5) -> 1.1241981 | J5: =MAX('1'!G5,'2'!G5) -> 1.1967132 | K5: =MAX('1'!H5,'2'!H5) -> 1.2628425 | L5: =MAX('1'!I5,'2'!I5) -> 1.30107 | M5: =MAX('1'!J5,'2'!J5) -> 1.3535401 | ... NY5: =MAX('1'!NV5,'2'!NV5) -> 15.478377
A6: 4 | B6: H-306 | C6: NEG | F6: =MAX('1'!C6,'2'!C6) -> 0.8335048 | G6: =MAX('1'!D6,'2'!D6) -> 0.96879734 | H6: =MAX('1'!E6,'2'!E6) -> 1.0765011 | I6: =MAX('1'!F6,'2'!F6) -> 1.1566163 | J6: =MAX('1'!G6,'2'!G6) -> 1.2091426 | K6: =MAX('1'!H6,'2'!H6) -> 1.2340803 | L6: =MAX('1'!I6,'2'!I6) -> 1.1515128 | M6: =MAX('1'!J6,'2'!J6) -> 1.1133948 | ... NY6: =MAX('1'!NV6,'2'!NV6) -> 12.353792
A7: 5 | B7: H-312 | C7: NEG | F7: =MAX('1'!C7,'2'!C7) -> 0.92895189 | G7: =MAX('1'!D7,'2'!D7) -> 1.0119517 | H7: =MAX('1'!E7,'2'!E7) -> 1.0900755 | I7: =MAX('1'!F7,'2'!F7) -> 1.1633231 | J7: =MAX('1'!G7,'2'!G7) -> 1.2316944 | K7: =MAX('1'!H7,'2'!H7) -> 1.2951896 | L7: =MAX('1'!I7,'2'!I7) -> 1.3359744 | M7: =MAX('1'!J7,'2'!J7) -> 1.3856024 | ... NY7: =MAX('1'!NV7,'2'!NV7) -> 13.767953
A8: 6 | B8: H-405 | C8: NEG | F8: =MAX('1'!C8,'2'!C8) -> 0.70404238 | G8: =MAX('1'!D8,'2'!D8) -> 0.82674564 | H8: =MAX('1'!E8,'2'!E8) -> 0.92479567 | I8: =MAX('1'!F8,'2'!F8) -> 0.99819241 | J8: =MAX('1'!G8,'2'!G8) -> 1.046936 | K8: =MAX('1'!H8,'2'!H8) -> 1.0710264 | L8: =MAX('1'!I8,'2'!I8) -> 1.0041565 | M8: =MAX('1'!J8,'2'!J8) -> 0.97032455 | ... NY8: =MAX('1'!NV8,'2'!NV8) -> 12.793659
A9: 7 | B9: H-411 | C9: NEG | F9: =MAX('1'!C9,'2'!C9) -> 0.80695263 | G9: =MAX('1'!D9,'2'!D9) -> 0.89904166 | H9: =MAX('1'!E9,'2'!E9) -> 0.98515932 | I9: =MAX('1'!F9,'2'!F9) -> 1.0653056 | J9: =MAX('1'!G9,'2'!G9) -> 1.1394804 | K9: =MAX('1'!H9,'2'!H9) -> 1.2076839 | L9: =MAX('1'!I9,'2'!I9) -> 1.2484612 | M9: =MAX('1'!J9,'2'!J9) -> 1.2957232 | ... NY9: =MAX('1'!NV9,'2'!NV9) -> 13.569646
A10: 8 | B10: H-502 | C10: NEG | F10: =MAX('1'!C10,'2'!C10) -> 0.85381036 | G10: =MAX('1'!D10,'2'!D10) -> 0.96892689 | H10: =MAX('1'!E10,'2'!E10) -> 1.0599698 | I10: =MAX('1'!F10,'2'!F10) -> 1.1269391 | J10: =MAX('1'!G10,'2'!G10) -> 1.1698346 | K10: =MAX('1'!H10,'2'!H10) -> 1.1886566 | L10: =MAX('1'!I10,'2'!I10) -> 1.1102044 | M10: =MAX('1'!J10,'2'!J10) -> 1.0737361 | ... NY10: =MAX('1'!NV10,'2'!NV10) -> 13.47746
A11: 9 | B11: H-509 | C11: NEG | F11: =MAX('1'!C11,'2'!C11) -> 0.86428052 | G11: =MAX('1'!D11,'2'!D11) -> 0.95790567 | H11: =MAX('1'!E11,'2'!E11) -> 1.0446945 | I11: =MAX('1'!F11,'2'!F11) -> 1.1246472 | J11: =MAX('1'!G11,'2'!G11) -> 1.1977634 | K11: =MAX('1'!H11,'2'!H11) -> 1.2640435 | L11: =MAX('1'!I11,'2'!I11) -> 1.3095875 | M11: =MAX('1'!J11,'2'!J11) -> 1.3510939 | ... NY11: =MAX('1'!NV11,'2'!NV11) -> 13.330729
A12: 10 | B12: L-108 | C12: NEG | F12: =MAX('1'!C12,'2'!C12) -> 0.97093881 | G12: =MAX('1'!D12,'2'!D12) -> 1.042828 | H12: =MAX('1'!E12,'2'!E12) -> 1.111743 | I12: =MAX('1'!F12,'2'!F12) -> 1.1776836 | J12: =MAX('1'!G12,'2'!G12) -> 1.2406503 | K12: =MAX('1'!H12,'2'!H12) -> 1.3006428 | L12: =MAX('1'!I12,'2'!I12) -> 1.3335579 | M12: =MAX('1'!J12,'2'!J12) -> 1.382594 | ... NY12: =MAX('1'!NV12,'2'!NV12) -> 14.89377
A13: 11 | B13: L-111 | C13: NEG | F13: =MAX('1'!C13,'2'!C13) -> 1.122428 | G13: =MAX('1'!D13,'2'!D13) -> 1.2217255 | H13: =MAX('1'!E13,'2'!E13) -> 1.3146127 | I13: =MAX('1'!F13,'2'!F13) -> 1.4010898 | J13: =MAX('1'!G13,'2'!G13) -> 1.4811566 | K13: =MAX('1'!H13,'2'!H13) -> 1.554813 | L13: =MAX('1'!I13,'2'!I13) -> 1.5981078 | M13: =MAX('1'!J13,'2'!J13) -> 1.650668 | ... NY13: =MAX('1'!NV13,'2'!NV13) -> 15.914471
... A35: 33 | B35: L-511 | C35: POS | F35: =MAX('1'!C35,'2'!C35) -> 0.77004283 | G35: =MAX('1'!D35,'2'!D35) -> 0.84942892 | H35: =MAX('1'!E35,'2'!E35) -> 0.92430388 | I35: =MAX('1'!F35,'2'!F35) -> 0.9946678 | J35: =MAX('1'!G35,'2'!G35) -> 1.0605205 | K35: =MAX('1'!H35,'2'!H35) -> 1.1218622 | L35: =MAX('1'!I35,'2'!I35) -> 1.1646981 | M35: =MAX('1'!J35,'2'!J35) -> 1.2110282 | ... NY35: =MAX('1'!NV35,'2'!NV35) -> 12.837438

Sheet 1
B1: PlotID | C1: 0.40534 | D1: 0.40853 | E1: 0.41173 | F1: 0.41492 | G1: 0.41811 | H1: 0.4213 | I1: 0.42449 | J1: 0.4277 | K1: 0.4309 | L1: 0.43411 | M1: 0.43732 | N1: 0.44053 | O1: 0.44374 | P1: 0.44695 | Q1: 0.45015 | R1: 0.45336 | S1: 0.45657 | T1: 0.45978 | U1: 0.46299 | V1: 0.46619 | W1: 0.4694 | X1: 0.47261 | Y1: 0.47582 | Z1: 0.47903 | AA1: 0.4822 | AB1: 0.48534 | AC1: 0.48848 | AD1: 0.49162 | AE1: 0.49475 | AF1: 0.49789 | AG1: 0.50103 | AH1: 0.50417 | AI1: 0.50731 | AJ1: 0.51045 | AK1: 0.51359 | AL1: 0.51673 | AM1: 0.51986 | AN1: 0.52307 | AO1: 0.52631 | AP1: 0.52954 | AQ1: 0.53277 | AR1: 0.53601 | AS1: 0.53924 | AT1: 0.54247 | AU1: 0.54571 | AV1: 0.54894 | AW1: 0.55218 | AX1: 0.55541 | AY1: 0.55864 | AZ1: 0.56188 | BA1: 0.56511 | BB1: 0.56835 | BC1: 0.57158 | BD1: 0.57481 | BE1: 0.57805 | BF1: 0.58128 | BG1: 0.58449 | BH1: 0.58766 | BI1: 0.59083 | BJ1: 0.59401 | BK1: 0.59718 | BL1: 0.60035 | BM1: 0.60353 | BN1: 0.6067 | BO1: 0.60987 | BP1: 0.61304 | BQ1: 0.61622 | BR1: 0.61939 | BS1: 0.62256 | BT1: 0.62574 | BU1: 0.62891 | BV1: 0.63208 | BW1: 0.63526 | BX1: 0.63843 | BY1: 0.6416 | BZ1: 0.64477 | CA1: 0.64795 | CB1: 0.65112 | CC1: 0.65429 | CD1: 0.65747 | CE1: 0.66064 | CF1: 0.66381 | CG1: 0.66699 | CH1: 0.67016 | CI1: 0.67333 | CJ1: 0.6765 | CK1: 0.67968 | CL1: 0.68287 | CM1: 0.68608 | CN1: 0.68929 | CO1: 0.6925 | CP1: 0.69571 | CQ1: 0.69892 | CR1: 0.70213 | CS1: 0.70534 | CT1: 0.70854 | CU1: 0.71175 | CV1: 0.71496 | CW1: 0.71817 | CX1: 0.72138 | CY1: 0.72459 | CZ1: 0.7278 | DA1: 0.73101 | DB1: 0.73422 | DC1: 0.73743 | DD1: 0.74063 | DE1: 0.74384 | DF1: 0.74705 | DG1: 0.75026 | DH1: 0.75347 | DI1: 0.75668 | DJ1: 0.75989 | DK1: 0.7631 | DL1: 0.7663 | DM1: 0.76951 | DN1: 0.77271 | DO1: 0.77592 | DP1: 0.77912 | DQ1: 0.78233 | DR1: 0.78553 | DS1: 0.78874 | DT1: 0.79194 | DU1: 0.79515 | DV1: 0.79835 | DW1: 0.80156 | DX1: 0.80476 | DY1: 0.80797 | DZ1: 0.81118 | EA1: 0.81438 | EB1: 0.81758 | EC1: 0.82077 | ED1: 0.82396 | EE1: 0.82714 | EF1: 0.83033 | EG1: 0.83352 | EH1: 0.83671 | EI1: 0.8399 | EJ1: 0.84308 | EK1: 0.84627 | EL1: 0.84946 | EM1: 0.85265 | EN1: 0.85584 | EO1: 0.85903 | EP1: 0.86221 | EQ1: 0.8654 | ER1: 0.86859 | ES1: 0.87178 | ET1: 0.87496 | EU1: 0.87815 | EV1: 0.88134 | EW1: 0.88453 | EX1: 0.88771 | EY1: 0.8909 | EZ1: 0.89409 | FA1: 0.89728 | FB1: 0.90047 | FC1: 0.90365 | FD1: 0.90684 | FE1: 0.91003 | FF1: 0.91322 | FG1: 0.91641 | FH1: 0.91959 | FI1: 0.92278 | FJ1: 0.92597 | FK1: 0.92916 | FL1: 0.93235 | FM1: 0.93553 | FN1: 0.93872 | FO1: 0.94191 | FP1: 0.9451 | FQ1: 0.9483 | FR1: 0.95056 | FS1: 0.95149 | FT1: 0.95468 | FU1: 0.95601 | FV1: 0.95787 | FW1: 0.96106 | FX1: 0.96147 | FY1: 0.96426 | FZ1: 0.96692 | GA1: 0.96745 | GB1: 0.97064 | GC1: 0.97237 | GD1: 0.97383 | GE1: 0.97702 | GF1: 0.97782 | GG1: 0.98022 | GH1: 0.98327 | GI1: 0.98341 | GJ1: 0.9866 | GK1: 0.98873 | GL1: 0.98979 | GM1: 0.99298 | GN1: 0.99418 | GO1: 0.99618 | GP1: 0.99963 | GQ1: 1.00508 | GR1: 1.01053 | GS1: 1.01599 | GT1: 1.02144 | GU1: 1.02689 | GV1: 1.03235 | GW1: 1.0378 | GX1: 1.04325 | GY1: 1.0487 | GZ1: 1.05416 | HA1: 1.05961 | HB1: 1.06506 | HC1: 1.07052 | HD1: 1.07597 | HE1: 1.08142 | HF1: 1.08687 | HG1: 1.09232 | HH1: 1.09777 | HI1: 1.10323 | HJ1: 1.1087 | HK1: 1.11416 | HL1: 1.11963 | HM1: 1.1251 | HN1: 1.13057 | HO1: 1.13603 | HP1: 1.1415 | HQ1: 1.14697 | HR1: 1.15243 | HS1: 1.1579 | HT1: 1.16337 | HU1: 1.16884 | HV1: 1.1743 | HW1: 1.17977 | HX1: 1.18524 | HY1: 1.1907 | HZ1: 1.19616 | IA1: 1.20164 | IB1: 1.2071 | IC1: 1.21256 | ID1: 1.21803 | IE1: 1.2235 | IF1: 1.22896 | IG1: 1.23443 | IH1: 1.2399 | II1: 1.24536 | IJ1: 1.25083 | IK1: 1.25628 | IL1: 1.26171 | IM1: 1.26715 | IN1: 1.27258 | IO1: 1.27801 | IP1: 1.28344 | IQ1: 1.28888 | IR1: 1.50086 | IS1: 1.50631 | IT1: 1.51176 | IU1: 1.51722 | IV1: 1.52267 | IW1: 1.52813 | IX1: 1.53358 | IY1: 1.53902 | IZ1: 1.54448 | JA1: 1.54993 | JB1: 1.55538 | JC1: 1.56084 | JD1: 1.56629 | JE1: 1.57174 | JF1: 1.5772 | JG1: 1.58265 | JH1: 1.58811 | JI1: 1.59358 | JJ1: 1.59904 | JK1: 1.60451 | JL1: 1.60998 | JM1: 1.61544 | JN1: 1.62091 | JO1: 1.62638 | JP1: 1.63183 | JQ1: 1.63731 | JR1: 1.64277 | JS1: 1.64823 | JT1: 1.6537 | JU1: 1.65916 | JV1: 1.66463 | JW1: 1.6701 | JX1: 1.67556 | JY1: 1.68103 | JZ1: 1.68649 | KA1: 1.69196 | KB1: 1.69743 | KC1: 1.70289 | KD1: 1.70836 | KE1: 1.71383 | KF1: 1.71929 | KG1: 1.72476 | KH1: 1.73022 | KI1: 1.73569 | KJ1: 1.74116 | KK1: 1.74662 | KL1: 1.75208 | KM1: 1.75756 | KN1: 1.76301 | KO1: 1.76848 | KP1: 1.77394 | KQ1: 1.77941 | KR1: 1.78488 | KS1: 1.79034 | KT1: 1.79581 | KU1: 1.80128 | KV1: 1.80674 | KW1: 1.81221 | KX1: 1.81767 | KY1: 1.82314 | KZ1: 1.99257 | LA1: 1.99804 | LB1: 2.0035 | LC1: 2.00895 | LD1: 2.0144 | LE1: 2.01984 | LF1: 2.02529 | LG1: 2.03074 | LH1: 2.03618 | LI1: 2.04163 | LJ1: 2.04708 | LK1: 2.05252 | LL1: 2.05797 | LM1: 2.0634 | LN1: 2.06882 | LO1: 2.07425 | LP1: 2.07967 | LQ1: 2.0851 | LR1: 2.09053 | LS1: 2.09596 | LT1: 2.10138 | LU1: 2.10681 | LV1: 2.11224 | LW1: 2.11767 | LX1: 2.1231 | LY1: 2.12853 | LZ1: 2.13396 | MA1: 2.13938 | MB1: 2.14481 | MC1: 2.15024 | MD1: 2.15567 | ME1: 2.1611 | MF1: 2.16653 | MG1: 2.17195 | MH1: 2.17738 | MI1: 2.18281 | MJ1: 2.18824 | MK1: 2.19367 | ML1: 2.19912 | MM1: 2.20461 | MN1: 2.2101 | MO1: 2.21559 | MP1: 2.22109 | MQ1: 2.22658 | MR1: 2.23208 | MS1: 2.23757 | MT1: 2.24306 | MU1: 2.24856 | MV1: 2.25405 | MW1: 2.25955 | MX1: 2.26504 | MY1: 2.27053 | MZ1: 2.27603 | NA1: 2.28152 | NB1: 2.28702 | NC1: 2.29251 | ND1: 2.298 | NE1: 2.30349 | NF1: 2.30898 | NG1: 2.31446 | NH1: 2.3199 | NI1: 2.32534 | NJ1: 2.33077 | NK1: 2.33621 | NL1: 2.34165 | NM1: 2.34708 | NN1: 2.35252 | NO1: 2.35795 | NP1: 2.36339 | NQ1: 2.36883 | NR1: 2.37426 | NS1: 2.3797 | NT1: 2.38514 | NU1: 2.39057 | NV1: 2.39601
A2: 0 | B2: H-102_NEG | C2: 0.91266267 | D2: 1.025977 | E2: 1.1147119 | F2: 1.1788673 | G2: 1.2184433 | H2: 1.23344 | I2: 1.1504081 | J2: 1.108903 | K2: 1.1243014 | L2: 1.1613665 | M2: 1.2358311 | N2: 1.3304118 | O2: 1.4461381 | P2: 1.596071 | Q2: 1.7913706 | R2: 1.6980799 | S2: 1.7122831 | T2: 1.726652 | U2: 1.7394998 | V2: 1.7635059 | W2: 1.803479 | X2: 1.8260131 | Y2: 1.8736045 | Z2: 1.9272641 | AA2: 1.9788002 | AB2: 2.019832 | AC2: 2.0705762 | AD2: 2.1290572 | AE2: 2.188552 | AF2: 2.2803257 | AG2: 2.3844913 | AH2: 2.4999241 | AI2: 2.679991 | AJ2: 2.8608692 | AK2: 3.0525375 | AL2: 3.2715767 | AM2: 3.5122125 | AN2: 3.7611575 | AO2: 4.0024182 | AP2: 4.2391769 | AQ2: 4.436929 | AR2: 4.6085112 | AS2: 4.7550301 | AT2: 4.8700872 | AU2: 4.9826374 | AV2: 5.088373 | AW2: 5.1548447 | AX2: 5.2294617 | AY2: 5.2735457 | AZ2: 5.3000284 | BA2: 5.2789614 | BB2: 5.2127929 | BC2: 5.1434024 | BD2: 5.130913 | BE2: 5.1163846 | BF2: 5.0969279 | BG2: 5.0723243 | BH2: 5.0727539 | BI2: 5.0615921 | BJ2: 5.0657561 | BK2: 5.0580532 | BL2: 5.0656265 | BM2: 5.0751689 | BN2: 5.0952362 | BO2: 5.0948757 | BP2: 5.0974244 | BQ2: 5.0844904 | BR2: 5.0680257 | BS2: 5.0434925 | BT2: 5.0386988 | BU2: 5.0366752 | BV2: 5.0626932 | BW2: 5.0432647 | BX2: 5.0026324 | BY2: 5.0001014 | BZ2: 4.9497952 | CA2: 4.8691083 | CB2: 4.7873622 | CC2: 4.7028731 | CD2: 4.6367342 | CE2: 4.5885353 | CF2: 4.5621245 | CG2: 4.5039481 | CH2: 4.4888814 | CI2: 4.6220158 | CJ2: 4.6975452 | CK2: 4.7855977 | CL2: 4.9303904 | CM2: 5.2226772 | CN2: 5.6342687 | CO2: 6.163186 | CP2: 6.7955329 | CQ2: 7.4446542 | CR2: 8.283445 | CS2: 9.3286051 | CT2: 10.137692 | CU2: 10.913649 | CV2: 11.641214 | CW2: 12.28787 | CX2: 12.815417 | CY2: 13.277487 | CZ2: 13.658991 | DA2: 13.961483 | DB2: 14.35343 | DC2: 14.764701 | DD2: 15.041531 | DE2: 15.243097 | DF2: 15.407148 | DG2: 15.732724 | DH2: 16.090037 | DI2: 16.389392 | DJ2: 16.61716 | DK2: 16.798119 | DL2: 16.948488 | DM2: 17.037258 | DN2: 17.071666 | DO2: 16.961427 | DP2: 16.960534 | DQ2: 17.176487 | DR2: 17.333104 | DS2: 17.433703 | DT2: 17.541003 | DU2: 17.639767 | DV2: 17.705751 | DW2: 17.76764 | DX2: 17.908287 | DY2: 18.022894 | DZ2: 18.207993 | EA2: 18.386588 | EB2: 18.536804 | EC2: 18.673304 | ED2: 18.786175 | EE2: 18.883211 | EF2: 18.955696 | EG2: 19.049086 | EH2: 19.213567 | EI2: 19.291705 | EJ2: 19.479869 | EK2: 19.612101 | EL2: 19.682977 | EM2: 19.755659 | EN2: 19.902296 | EO2: 20.01333 | EP2: 20.120094 | EQ2: 20.213193 | ER2: 20.331189 | ES2: 20.414637 | ET2: 20.578583 | EU2: 20.682474 | EV2: 20.724235 | EW2: 20.749858 | EX2: 20.924159 | EY2: 21.044858 | EZ2: 21.109075 | FA2: 21.231185 | FB2: 21.368506 | FC2: 21.532632 | FD2: 21.703992 | FE2: 21.843817 | FF2: 21.921793 | FG2: 21.799428 | FH2: 21.667692 | FI2: 21.747056 | FJ2: 22.061849 | FK2: 22.231971 | FL2: 22.529093 | FM2: 23.043749 | FN2: 23.046251 | FO2: 23.02885 | FP2: 23.307099 | FQ2: 22.528348 | FR2: 21.830558 | FS2: 21.926338 | FT2: 21.421122 | FU2: 21.197226 | FV2: 20.959254 | FW2: 21.120363 | FX2: 21.256127 | FY2: 21.39328 | FZ2: 21.809818 | GA2: 21.780523 | GB2: 21.864358 | GC2: 22.432666 | GD2: 21.979789 | GE2: 22.219128 | GF2: 22.232007 | GG2: 22.399914 | GH2: 22.648681 | GI2: 22.719477 | GJ2: 22.779935 | GK2: 23.227997 | GL2: 23.163277 | GM2: 23.227181 | GN2: 22.86079 | GO2: 22.779615 | GP2: 22.868213 | GQ2: 22.917861 | GR2: 23.26341 | GS2: 23.735186 | GT2: 23.883267 | GU2: 24.215215 | GV2: 24.233373 | GW2: 24.194356 | GX2: 24.233864 | GY2: 24.51349 | GZ2: 25.0105 | HA2: 25.602681 | HB2: 26.050372 | HC2: 26.295282 | HD2: 26.258365 | HE2: 26.116202 | HF2: 25.972474 | HG2: 26.004797 | HH2: 26.027046 | HI2: 26.257829 | HJ2: 26.204078 | HK2: 26.197911 | HL2: 25.763794 | HM2: 25.229127 | HN2: 24.662237 | HO2: 24.218066 | HP2: 23.945556 | HQ2: 23.894355 | HR2: 23.987337 | HS2: 24.336654 | HT2: 24.503541 | HU2: 24.809667 | HV2: 24.768657 | HW2: 24.717859 | HX2: 24.59563 | HY2: 24.474269 | HZ2: 24.403715 | IA2: 24.485639 | IB2: 24.735113 | IC2: 25.07791 | ID2: 25.429928 | IE2: 25.752964 | IF2: 26.027038 | IG2: 26.206164 | IH2: 26.285334 | II2: 26.451336 | IJ2: 26.561294 | IK2: 26.680444 | IL2: 26.757634 | IM2: 26.81374 | IN2: 26.849278 | IO2: 26.864256 | IP2: 26.858669 | IQ2: 26.832519 | IR2: 15.919936 | IS2: 16.390243 | IT2: 16.839025 | IU2: 17.266283 | IV2: 17.672015 | IW2: 18.056224 | IX2: 18.439304 | IY2: 18.758795 | IZ2: 18.987423 | JA2: 19.348595 | JB2: 19.560772 | JC2: 19.730261 | JD2: 19.929069 | JE2: 20.049003 | JF2: 20.17537 | JG2: 20.221183 | JH2: 20.505387 | JI2: 20.721827 | JJ2: 20.865231 | JK2: 21.136791 | JL2: 21.301367 | JM2: 21.411287 | JN2: 21.587349 | JO2: 21.696407 | JP2: 21.757351 | JQ2: 21.868226 | JR2: 22.131974 | JS2: 22.290841 | JT2: 22.358891 | JU2: 22.505463 | JV2: 22.574772 | JW2: 22.578012 | JX2: 22.6079 | JY2: 22.544704 | JZ2: 22.427018 | KA2: 22.349111 | KB2: 22.175621 | KC2: 22.00359 | KD2: 21.698655 | KE2: 21.560267 | KF2: 21.398656 | KG2: 21.327258 | KH2: 21.210479 | KI2: 21.127313 | KJ2: 21.039759 | KK2: 21.031505 | KL2: 20.906626 | KM2: 20.782872 | KN2: 20.532067 | KO2: 20.376777 | KP2: 20.184729 | KQ2: 19.999731 | KR2: 19.735715 | KS2: 19.499865 | KT2: 19.223458 | KU2: 18.953218 | KV2: 18.674585 | KW2: 18.387555 | KX2: 18.092135 | KY2: 17.788321 | KZ2: 12.896293 | LA2: 13.194119 | LB2: 13.437642 | LC2: 13.626862 | LD2: 13.761781 | LE2: 13.842397 | LF2: 13.589585 | LG2: 13.529143 | LH2: 13.633914 | LI2: 13.654722 | LJ2: 13.785627 | LK2: 13.856286 | LL2: 13.893953 | LM2: 13.912224 | LN2: 13.901921 | LO2: 13.884164 | LP2: 13.896841 | LQ2: 13.967375 | LR2: 13.941759 | LS2: 13.966841 | LT2: 13.988676 | LU2: 14.071274 | LV2: 14.115065 | LW2: 14.201887 | LX2: 14.244735 | LY2: 14.320474 | LZ2: 14.398516 | MA2: 14.441635 | MB2: 14.488681 | MC2: 14.521749 | MD2: 14.544409 | ME2: 14.593608 | MF2: 14.61643 | MG2: 14.738264 | MH2: 14.967817 | MI2: 15.244884 | MJ2: 15.461254 | MK2: 15.638617 | ML2: 15.767247 | MM2: 15.809663 | MN2: 15.780424 | MO2: 15.698935 | MP2: 15.605356 | MQ2: 15.565855 | MR2: 15.568796 | MS2: 15.491682 | MT2: 15.311143 | MU2: 15.050069 | MV2: 14.754341 | MW2: 14.427507 | MX2: 14.132084 | MY2: 13.869874 | MZ2: 13.683835 | NA2: 13.509496 | NB2: 13.299232 | NC2: 13.134689 | ND2: 12.991315 | NE2: 12.807159 | NF2: 12.651413 | NG2: 12.530819 | NH2: 12.441621 | NI2: 12.411424 | NJ2: 12.419318 | NK2: 12.364379 | NL2: 12.205747 | NM2: 12.276658 | NN2: 12.376683 | NO2: 12.43044 | NP2: 12.486662 | NQ2: 12.541452 | NR2: 12.53243 | NS2: 12.496987 | NT2: 12.435125 | NU2: 12.346843 | NV2: 12.232144
A3: 1 | B3: H-115_NEG | C3: 0.94503894 | D3: 0.99868976 | E3: 1.0529367 | F3: 1.10778 | G3: 1.1632193 | H3: 1.2192549 | I3: 1.2601508 | J3: 1.3251818 | K3: 1.3901638 | L3: 1.462535 | M3: 1.5192672 | N3: 1.5713237 | O3: 1.5920958 | P3: 1.6154667 | Q3: 1.6624395 | R3: 1.6837268 | S3: 1.6895366 | T3: 1.7053871 | U3: 1.71881 | V3: 1.7494161 | W3: 1.7961512 | X3: 1.8282025 | Y3: 1.8816494 | Z3: 1.9488997 | AA3: 2.0054697 | AB3: 2.0384032 | AC3: 2.0841993 | AD3: 2.1405126 | AE3: 2.1998548 | AF3: 2.292364 | AG3: 2.3963682 | AH3: 2.5059951 | AI3: 2.6724091 | AJ3: 2.8282981 | AK3: 2.9875311 | AL3: 3.1593087 | AM3: 3.3616432 | AN3: 3.5654692 | AO3: 3.767071 | AP3: 3.9738965 | AQ3: 4.1515143 | AR3: 4.307433 | AS3: 4.4433031 | AT3: 4.5452593 | AU3: 4.6529543 | AV3: 4.74566 | AW3: 4.8095712 | AX3: 4.8791741 | AY3: 4.9274249 | AZ3: 4.9663431 | BA3: 4.9725426 | BB3: 4.9331633 | BC3: 4.8971177 | BD3: 4.9091372 | BE3: 4.9210051 | BF3: 4.9186542 | BG3: 4.9038382 | BH3: 4.9144866 | BI3: 4.91812 | BJ3: 4.9391149 | BK3: 4.9466915 | BL3: 4.9608812 | BM3: 4.9847514 | BN3: 5.0202605 | BO3: 5.0365092 | BP3: 5.0551906 | BQ3: 5.0558974 | BR3: 5.056677 | BS3: 5.0477668 | BT3: 5.0500759 | BU3: 5.0517441 | BV3: 5.0796521 | BW3: 5.0715095 | BX3: 5.0501799 | BY3: 5.0700289 | BZ3: 5.0410411 | CA3: 4.9785625 | CB3: 4.9126445 | CC3: 4.8405382 | CD3: 4.7871262 | CE3: 4.7520247 | CF3: 4.7419668 | CG3: 4.7009395 | CH3: 4.701043 | CI3: 4.8553469 | CJ3: 4.9406056 | CK3: 5.0260898 | CL3: 5.1573981 | CM3: 5.4208848 | CN3: 5.7945999 | CO3: 6.2520516 | CP3: 6.7994049 | CQ3: 7.3600636 | CR3: 8.0820462 | CS3: 9.0446368 | CT3: 9.7709422 | CU3: 10.454365 | CV3: 11.112347 | CW3: 11.69162 | CX3: 12.159904 | CY3: 12.546046 | CZ3: 12.869042 | DA3: 13.119132 | DB3: 13.457695 | DC3: 13.842097 | DD3: 14.112922 | DE3: 14.258924 | DF3: 14.443863 | DG3: 14.825447 | DH3: 15.240969 | DI3: 15.560166 | DJ3: 15.788378 | DK3: 15.946228 | DL3: 16.094459 | DM3: 16.152387 | DN3: 16.158222 | DO3: 15.9789 | DP3: 15.998051 | DQ3: 16.259192 | DR3: 16.44487 | DS3: 16.551439 | DT3: 16.651518 | DU3: 16.774015 | DV3: 16.863293 | DW3: 16.918998 | DX3: 17.078288 | DY3: 17.179613 | DZ3: 17.382458 | EA3: 17.54547 | EB3: 17.68118 | EC3: 17.835303 | ED3: 17.967451 | EE3: 18.117949 | EF3: 18.179549 | EG3: 18.270611 | EH3: 18.437917 | EI3: 18.480745 | EJ3: 18.661318 | EK3: 18.765683 | EL3: 18.80618 | EM3: 18.922595 | EN3: 19.113433 | EO3: 19.25803 | EP3: 19.35144 | EQ3: 19.467369 | ER3: 19.570065 | ES3: 19.653797 | ET3: 19.800096 | EU3: 19.88865 | EV3: 19.891743 | EW3: 19.885851 | EX3: 20.056721 | EY3: 20.131877 | EZ3: 20.210204 | FA3: 20.37302 | FB3: 20.514247 | FC3: 20.701861 | FD3: 20.909495 | FE3: 21.090935 | FF3: 21.137473 | FG3: 20.934551 | FH3: 20.844432 | FI3: 20.937368 | FJ3: 21.230944 | FK3: 21.356847 | FL3: 21.616626 | FM3: 22.198148 | FN3: 22.117634 | FO3: 21.966066 | FP3: 22.190006 | FQ3: 21.39813 | FR3: 20.729868 | FS3: 20.78906 | FT3: 20.270396 | FU3: 20.105502 | FV3: 19.967367 | FW3: 20.247018 | FX3: 20.333656 | FY3: 20.36863 | FZ3: 20.861195 | GA3: 20.947676 | GB3: 21.033497 | GC3: 21.610208 | GD3: 21.149066 | GE3: 21.388486 | GF3: 21.427909 | GG3: 21.532339 | GH3: 21.700024 | GI3: 21.623379 | GJ3: 21.626859 | GK3: 22.117212 | GL3: 21.977953 | GM3: 21.994547 | GN3: 21.539391 | GO3: 21.467277 | GP3: 21.596304 | GQ3: 21.567565 | GR3: 21.836478 | GS3: 22.213539 | GT3: 22.234946 | GU3: 22.507482 | GV3: 22.472189 | GW3: 22.446812 | GX3: 22.521513 | GY3: 22.847416 | GZ3: 23.351958 | HA3: 23.863978 | HB3: 24.218337 | HC3: 24.376472 | HD3: 24.291884 | HE3: 24.176955 | HF3: 24.097443 | HG3: 24.17849 | HH3: 24.255318 | HI3: 24.543097 | HJ3: 24.492975 | HK3: 24.576961 | HL3: 24.213871 | HM3: 23.816048 | HN3: 23.433635 | HO3: 23.215625 | HP3: 23.086841 | HQ3: 23.114535 | HR3: 23.227868 | HS3: 23.541909 | HT3: 23.629518 | HU3: 23.908544 | HV3: 23.754152 | HW3: 23.670653 | HX3: 23.566831 | HY3: 23.493033 | HZ3: 23.477235 | IA3: 23.593811 | IB3: 23.848754 | IC3: 24.188837 | ID3: 24.522957 | IE3: 24.82215 | IF3: 25.034251 | IG3: 25.155218 | IH3: 25.204553 | II3: 25.329959 | IJ3: 25.430651 | IK3: 25.527999 | IL3: 25.620521 | IM3: 25.699687 | IN3: 25.771764 | IO3: 25.836757 | IP3: 25.894663 | IQ3: 25.945483 | IR3: 17.254636 | IS3: 17.723625 | IT3: 18.173258 | IU3: 18.603537 | IV3: 19.014462 | IW3: 19.40603 | IX3: 19.805094 | IY3: 20.156853 | IZ3: 20.391234 | JA3: 20.748456 | JB3: 20.959037 | JC3: 21.083361 | JD3: 21.275485 | JE3: 21.360276 | JF3: 21.463388 | JG3: 21.483421 | JH3: 21.750346 | JI3: 21.98833 | JJ3: 22.108643 | JK3: 22.396523 | JL3: 22.583825 | JM3: 22.653709 | JN3: 22.863224 | JO3: 22.953592 | JP3: 23.006854 | JQ3: 23.114748 | JR3: 23.375416 | JS3: 23.563269 | JT3: 23.634867 | JU3: 23.786212 | JV3: 23.870124 | JW3: 23.872866 | JX3: 23.93604 | JY3: 23.87522 | JZ3: 23.79137 | KA3: 23.728626 | KB3: 23.573946 | KC3: 23.439495 | KD3: 23.133186 | KE3: 22.982366 | KF3: 22.850584 | KG3: 22.810529 | KH3: 22.720395 | KI3: 22.681674 | KJ3: 22.624375 | KK3: 22.630592 | KL3: 22.509559 | KM3: 22.395866 | KN3: 22.156373 | KO3: 22.049467 | KP3: 21.914354 | KQ3: 21.794379 | KR3: 21.595429 | KS3: 21.413987 | KT3: 21.160128 | KU3: 20.907269 | KV3: 20.632916 | KW3: 20.337072 | KX3: 20.019736 | KY3: 19.680907 | KZ3: 16.235536 | LA3: 16.490158 | LB3: 16.671302 | LC3: 16.778972 | LD3: 16.813165 | LE3: 16.773882 | LF3: 16.111334 | LG3: 15.479361 | LH3: 16.11234 | LI3: 16.062896 | LJ3: 16.152607 | LK3: 16.227577 | LL3: 16.255554 | LM3: 16.265559 | LN3: 16.231805 | LO3: 16.198406 | LP3: 16.184183 | LQ3: 16.240959 | LR3: 16.192348 | LS3: 16.206781 | LT3: 16.221718 | LU3: 16.285355 | LV3: 16.319779 | LW3: 16.390727 | LX3: 16.417747 | LY3: 16.479334 | LZ3: 16.556972 | MA3: 16.611333 | MB3: 16.65566 | MC3: 16.703529 | MD3: 16.68104 | ME3: 16.719565 | MF3: 16.753473 | MG3: 16.878247 | MH3: 17.132803 | MI3: 17.43264 | MJ3: 17.669351 | MK3: 17.851491 | ML3: 17.942644 | MM3: 17.943607 | MN3: 17.825763 | MO3: 17.73845 | MP3: 17.646558 | MQ3: 17.597089 | MR3: 17.676698 | MS3: 17.635102 | MT3: 17.440641 | MU3: 17.155713 | MV3: 16.802339 | MW3: 16.450184 | MX3: 16.093922 | MY3: 15.774328 | MZ3: 15.527188 | NA3: 15.250905 | NB3: 15.106217 | NC3: 14.922542 | ND3: 14.76467 | NE3: 14.636743 | NF3: 14.488786 | NG3: 14.468861 | NH3: 14.375025 | NI3: 14.298551 | NJ3: 14.284347 | NK3: 14.23434 | NL3: 14.147947 | NM3: 14.314806 | NN3: 14.484355 | NO3: 14.655911 | NP3: 14.684028 | NQ3: 14.772836 | NR3: 14.762751 | NS3: 14.696257 | NT3: 14.573352 | NU3: 14.394039 | NV3: 14.158316
A4: 2 | B4: H-207_NEG | C4: 0.80691681 | D4: 0.96283107 | E4: 1.0872587 | F4: 1.1801997 | G4: 1.2416539 | H4: 1.2716215 | I4: 1.1879755 | J4: 1.1400947 | K4: 1.1500209 | L4: 1.1889143 | M4: 1.2622345 | N4: 1.3667185 | O4: 1.479124 | P4: 1.6342134 | Q4: 1.8452013 | R4: 1.762258 | S4: 1.7810124 | T4: 1.7999542 | U4: 1.8056493 | V4: 1.818191 | W4: 1.8504405 | X4: 1.8738984 | Y4: 1.9205885 | Z4: 1.9755175 | AA4: 2.0331323 | AB4: 2.0781649 | AC4: 2.1356244 | AD4: 2.1997714 | AE4: 2.2698838 | AF4: 2.3666097 | AG4: 2.4811307 | AH4: 2.6133653 | AI4: 2.8152816 | AJ4: 3.0204989 | AK4: 3.24999 | AL4: 3.5070396 | AM4: 3.7913336 | AN4: 4.0847478 | AO4: 4.383527 | AP4: 4.6610786 | AQ4: 4.8966188 | AR4: 5.1022346 | AS4: 5.2790684 | AT4: 5.4112745 | AU4: 5.5477986 | AV4: 5.6576859 | AW4: 5.7288716 | AX4: 5.7995212 | AY4: 5.8354324 | AZ4: 5.8439949 | BA4: 5.8027265 | BB4: 5.7107935 | BC4: 5.6163711 | BD4: 5.5810479 | BE4: 5.547052 | BF4: 5.5015549 | BG4: 5.4533068 | BH4: 5.4313883 | BI4: 5.407054 | BJ4: 5.4042807 | BK4: 5.3845705 | BL4: 5.3847047 | BM4: 5.3947861 | BN4: 5.4115397 | BO4: 5.3972812 | BP4: 5.3792756 | BQ4: 5.3518122 | BR4: 5.3272289 | BS4: 5.298392 | BT4: 5.2954975 | BU4: 5.2852845 | BV4: 5.3065184 | BW4: 5.2785087 | BX4: 5.2197128 | BY4: 5.2023777 | BZ4: 5.1274162 | CA4: 5.0335457 | CB4: 4.9335424 | CC4: 4.833571 | CD4: 4.7622545 | CE4: 4.692522 | CF4: 4.6526795 | CG4: 4.5796831 | CH4: 4.5406593 | CI4: 4.6717994 | CJ4: 4.7396716 | CK4: 4.8283866 | CL4: 4.9888916 | CM4: 5.3240739 | CN4: 5.8024235 | CO4: 6.4222248 | CP4: 7.1754804 | CQ4: 7.9577834 | CR4: 8.9383328 | CS4: 10.190072 | CT4: 11.165573 | CU4: 12.114504 | CV4: 13.02215 | CW4: 13.829075 | CX4: 14.495404 | CY4: 15.076321 | CZ4: 15.557841 | DA4: 15.95506 | DB4: 16.450189 | DC4: 16.967739 | DD4: 17.315352 | DE4: 17.526853 | DF4: 17.772878 | DG4: 18.21447 | DH4: 18.605381 | DI4: 18.897299 | DJ4: 19.094915 | DK4: 19.269664 | DL4: 19.422722 | DM4: 19.503576 | DN4: 19.510273 | DO4: 19.331929 | DP4: 19.387599 | DQ4: 19.650952 | DR4: 19.805399 | DS4: 19.902145 | DT4: 19.997555 | DU4: 20.098404 | DV4: 20.157887 | DW4: 20.247057 | DX4: 20.388206 | DY4: 20.513019 | DZ4: 20.731826 | EA4: 20.938899 | EB4: 21.143973 | EC4: 21.289769 | ED4: 21.396661 | EE4: 21.46327 | EF4: 21.535909 | EG4: 21.644877 | EH4: 21.800646 | EI4: 21.887414 | EJ4: 22.100072 | EK4: 22.245193 | EL4: 22.319987 | EM4: 22.398981 | EN4: 22.54036 | EO4: 22.642788 | EP4: 22.797809 | EQ4: 22.880847 | ER4: 22.97746 | ES4: 23.077821 | ET4: 23.255915 | EU4: 23.353136 | EV4: 23.379212 | EW4: 23.382723 | EX4: 23.572916 | EY4: 23.727662 | EZ4: 23.834132 | FA4: 23.999302 | FB4: 24.155143 | FC4: 24.354973 | FD4: 24.56279 | FE4: 24.712758 | FF4: 24.768721 | FG4: 24.585495 | FH4: 24.470401 | FI4: 24.646246 | FJ4: 25.014342 | FK4: 25.245115 | FL4: 25.52527 | FM4: 26.15709 | FN4: 26.027592 | FO4: 25.91658 | FP4: 26.174416 | FQ4: 25.148847 | FR4: 24.302365 | FS4: 24.483166 | FT4: 23.842786 | FU4: 23.690332 | FV4: 23.467675 | FW4: 23.719876 | FX4: 23.761056 | FY4: 23.85354 | FZ4: 24.24816 | GA4: 24.169797 | GB4: 24.201428 | GC4: 24.941732 | GD4: 24.377141 | GE4: 24.725034 | GF4: 24.856103 | GG4: 25.015063 | GH4: 25.355287 | GI4: 25.432663 | GJ4: 25.491419 | GK4: 26.031395 | GL4: 25.833098 | GM4: 25.835409 | GN4: 25.250946 | GO4: 25.051777 | GP4: 25.129791 | GQ4: 25.061674 | GR4: 25.468418 | GS4: 25.98238 | GT4: 26.114594 | GU4: 26.454706 | GV4: 26.445618 | GW4: 26.387469 | GX4: 26.456048 | GY4: 26.779221 | GZ4: 27.336192 | HA4: 27.975924 | HB4: 28.439413 | HC4: 28.666284 | HD4: 28.59768 | HE4: 28.413678 | HF4: 28.246627 | HG4: 28.300226 | HH4: 28.285312 | HI4: 28.252037 | HJ4: 28.419211 | HK4: 28.629517 | HL4: 28.311248 | HM4: 27.835664 | HN4: 27.269598 | HO4: 26.778487 | HP4: 26.415215 | HQ4: 26.225199 | HR4: 26.038821 | HS4: 26.078206 | HT4: 26.451884 | HU4: 26.794389 | HV4: 26.698335 | HW4: 26.630973 | HX4: 26.484554 | HY4: 26.326068 | HZ4: 26.270084 | IA4: 26.378724 | IB4: 26.657889 | IC4: 27.051717 | ID4: 27.446883 | IE4: 27.803782 | IF4: 28.077698 | IG4: 28.271069 | IH4: 28.337483 | II4: 28.462161 | IJ4: 28.559751 | IK4: 28.655204 | IL4: 28.734543 | IM4: 28.793921 | IN4: 28.839786 | IO4: 28.872144 | IP4: 28.890991 | IQ4: 28.896324 | IR4: 16.212576 | IS4: 16.733468 | IT4: 17.229567 | IU4: 17.700871 | IV4: 18.147379 | IW4: 18.569096 | IX4: 18.988656 | IY4: 19.33704 | IZ4: 19.603264 | JA4: 19.973804 | JB4: 20.210602 | JC4: 20.399811 | JD4: 20.620557 | JE4: 20.768444 | JF4: 20.90762 | JG4: 20.991169 | JH4: 21.304733 | JI4: 21.561082 | JJ4: 21.738799 | JK4: 22.033511 | JL4: 22.248289 | JM4: 22.3686 | JN4: 22.579089 | JO4: 22.71815 | JP4: 22.791672 | JQ4: 22.919331 | JR4: 23.192843 | JS4: 23.351149 | JT4: 23.417938 | JU4: 23.56736 | JV4: 23.63546 | JW4: 23.632854 | JX4: 23.666845 | JY4: 23.608977 | JZ4: 23.489871 | KA4: 23.397531 | KB4: 23.203905 | KC4: 23.014102 | KD4: 22.688116 | KE4: 22.523424 | KF4: 22.334256 | KG4: 22.260471 | KH4: 22.109323 | KI4: 22.017747 | KJ4: 21.900221 | KK4: 21.858445 | KL4: 21.697699 | KM4: 21.553432 | KN4: 21.276535 | KO4: 21.10333 | KP4: 20.902744 | KQ4: 20.715623 | KR4: 20.436995 | KS4: 20.202425 | KT4: 19.899803 | KU4: 19.609951 | KV4: 19.309416 | KW4: 18.998199 | KX4: 18.676298 | KY4: 18.343714 | KZ4: 12.66786 | LA4: 13.063499 | LB4: 13.387143 | LC4: 13.638789 | LD4: 13.81844 | LE4: 13.926095 | LF4: 13.719613 | LG4: 13.612232 | LH4: 13.655846 | LI4: 13.650534 | LJ4: 13.781013 | LK4: 13.854332 | LL4: 13.901536 | LM4: 13.92894 | LN4: 13.934234 | LO4: 13.930179 | LP4: 13.941159 | LQ4: 13.993757 | LR4: 13.988042 | LS4: 14.04135 | LT4: 14.071565 | LU4: 14.157022 | LV4: 14.244153 | LW4: 14.33931 | LX4: 14.391046 | LY4: 14.447153 | LZ4: 14.511804 | MA4: 14.541626 | MB4: 14.595335 | MC4: 14.659585 | MD4: 14.681141 | ME4: 14.777604 | MF4: 14.847288 | MG4: 14.990962 | MH4: 15.235512 | MI4: 15.510175 | MJ4: 15.735041 | MK4: 15.91445 | ML4: 16.030096 | MM4: 16.083021 | MN4: 16.046462 | MO4: 15.987588 | MP4: 15.894408 | MQ4: 15.88717 | MR4: 15.910273 | MS4: 15.892582 | MT4: 15.689224 | MU4: 15.408089 | MV4: 15.05277 | MW4: 14.708231 | MX4: 14.401542 | MY4: 14.122619 | MZ4: 13.906357 | NA4: 13.71048 | NB4: 13.512526 | NC4: 13.381365 | ND4: 13.186908 | NE4: 12.978428 | NF4: 12.802711 | NG4: 12.713012 | NH4: 12.679612 | NI4: 12.640577 | NJ4: 12.598865 | NK4: 12.542139 | NL4: 12.379189 | NM4: 12.446911 | NN4: 12.524276 | NO4: 12.545816 | NP4: 12.644266 | NQ4: 12.74143 | NR4: 12.731595 | NS4: 12.685649 | NT4: 12.603591 | NU4: 12.485424 | NV4: 12.331145
A5: 3 | B5: H-217_NEG | C5: 0.86833597 | D5: 0.96000941 | E5: 1.0452967 | F5: 1.1241981 | G5: 1.1967132 | H5: 1.2628425 | I5: 1.30107 | J5: 1.3535401 | K5: 1.4183641 | L5: 1.4758525 | M5: 1.5299911 | N5: 1.5836087 | O5: 1.6122835 | P5: 1.6428681 | Q5: 1.6912627 | R5: 1.7230662 | S5: 1.739276 | T5: 1.7578471 | U5: 1.7682375 | V5: 1.796132 | W5: 1.8329339 | X5: 1.8598747 | Y5: 1.9049229 | Z5: 1.9605897 | AA5: 2.0134934 | AB5: 2.056115 | AC5: 2.1091351 | AD5: 2.1640152 | AE5: 2.2269029 | AF5: 2.3200481 | AG5: 2.418765 | AH5: 2.5374564 | AI5: 2.710418 | AJ5: 2.8757126 | AK5: 3.0580767 | AL5: 3.2577842 | AM5: 3.4840299 | AN5: 3.7096484 | AO5: 3.9365699 | AP5: 4.1623535 | AQ5: 4.3554045 | AR5: 4.5327347 | AS5: 4.679611 | AT5: 4.7910131 | AU5: 4.9110775 | AV5: 5.0053407 | AW5: 5.0692574 | AX5: 5.134513 | AY5: 5.1783278 | AZ5: 5.2104315 | BA5: 5.2055702 | BB5: 5.1584131 | BC5: 5.1082658 | BD5: 5.1137945 | BE5: 5.1210059 | BF5: 5.1114561 | BG5: 5.0958831 | BH5: 5.1035338 | BI5: 5.0986514 | BJ5: 5.1084436 | BK5: 5.1113577 | BL5: 5.1252019 | BM5: 5.1447914 | BN5: 5.176969 | BO5: 5.1907625 | BP5: 5.2067482 | BQ5: 5.2071842 | BR5: 5.1981822 | BS5: 5.1768482 | BT5: 5.1801259 | BU5: 5.1843 | BV5: 5.2203365 | BW5: 5.2112294 | BX5: 5.1834713 | BY5: 5.1994815 | BZ5: 5.1579978 | CA5: 5.0859531 | CB5: 5.0077884 | CC5: 4.92686 | CD5: 4.8710676 | CE5: 4.8282289 | CF5: 4.8107167 | CG5: 4.7602125 | CH5: 4.7518758 | CI5: 4.9034834 | CJ5: 4.9851235 | CK5: 5.0790395 | CL5: 5.2217963 | CM5: 5.5014446 | CN5: 5.8869033 | CO5: 6.3743575 | CP5: 6.9461995 | CQ5: 7.5315541 | CR5: 8.2830967 | CS5: 9.2743541 | CT5: 10.01339 | CU5: 10.715472 | CV5: 11.380953 | CW5: 11.966619 | CX5: 12.430346 | CY5: 12.820891 | CZ5: 13.137477 | DA5: 13.380064 | DB5: 13.717403 | DC5: 14.100811 | DD5: 14.347817 | DE5: 14.477806 | DF5: 14.633181 | DG5: 15.030797 | DH5: 15.413946 | DI5: 15.700805 | DJ5: 15.914774 | DK5: 16.071887 | DL5: 16.188122 | DM5: 16.239194 | DN5: 16.218578 | DO5: 16.028172 | DP5: 16.037295 | DQ5: 16.310898 | DR5: 16.476377 | DS5: 16.584359 | DT5: 16.705078 | DU5: 16.817619 | DV5: 16.880893 | DW5: 16.941514 | DX5: 17.079711 | DY5: 17.16436 | DZ5: 17.341136 | EA5: 17.5122 | EB5: 17.652384 | EC5: 17.790326 | ED5: 17.904797 | EE5: 18.000416 | EF5: 18.060152 | EG5: 18.137131 | EH5: 18.290262 | EI5: 18.336823 | EJ5: 18.533673 | EK5: 18.65035 | EL5: 18.701794 | EM5: 18.779506 | EN5: 18.916891 | EO5: 19.013621 | EP5: 19.110252 | EQ5: 19.203025 | ER5: 19.311512 | ES5: 19.388935 | ET5: 19.552667 | EU5: 19.628582 | EV5: 19.649789 | EW5: 19.634923 | EX5: 19.802493 | EY5: 19.897202 | EZ5: 19.965859 | FA5: 20.136487 | FB5: 20.281304 | FC5: 20.484546 | FD5: 20.671652 | FE5: 20.809094 | FF5: 20.868335 | FG5: 20.653513 | FH5: 20.481156 | FI5: 20.593733 | FJ5: 20.982412 | FK5: 21.1747 | FL5: 21.435993 | FM5: 22.028864 | FN5: 21.953627 | FO5: 21.859689 | FP5: 22.031362 | FQ5: 21.183655 | FR5: 20.449817 | FS5: 20.611369 | FT5: 20.294489 | FU5: 20.146032 | FV5: 20.072898 | FW5: 20.39936 | FX5: 20.487855 | FY5: 20.576446 | FZ5: 20.970603 | GA5: 20.904446 | GB5: 20.925447 | GC5: 21.407355 | GD5: 21.03878 | GE5: 21.230408 | GF5: 21.268754 | GG5: 21.426572 | GH5: 21.631562 | GI5: 21.620252 | GJ5: 21.67051 | GK5: 22.063112 | GL5: 21.9775 | GM5: 21.973528 | GN5: 21.655458 | GO5: 21.608601 | GP5: 21.771185 | GQ5: 21.882257 | GR5: 22.199775 | GS5: 22.532906 | GT5: 22.610194 | GU5: 22.839283 | GV5: 22.806181 | GW5: 22.775174 | GX5: 22.884144 | GY5: 23.218694 | GZ5: 23.720399 | HA5: 24.215099 | HB5: 24.522191 | HC5: 24.626152 | HD5: 24.543915 | HE5: 24.417007 | HF5: 24.344767 | HG5: 24.449247 | HH5: 24.4988 | HI5: 24.765811 | HJ5: 24.668133 | HK5: 24.697884 | HL5: 24.287038 | HM5: 23.863325 | HN5: 23.489312 | HO5: 23.288752 | HP5: 23.201745 | HQ5: 23.280093 | HR5: 23.402545 | HS5: 23.768009 | HT5: 23.841114 | HU5: 24.111489 | HV5: 23.943204 | HW5: 23.859463 | HX5: 23.750304 | HY5: 23.662839 | HZ5: 23.63401 | IA5: 23.760009 | IB5: 24.039157 | IC5: 24.398802 | ID5: 24.727123 | IE5: 25.014978 | IF5: 25.235308 | IG5: 25.362805 | IH5: 25.385107 | II5: 25.483885 | IJ5: 25.552464 | IK5: 25.640122 | IL5: 25.736522 | IM5: 25.804954 | IN5: 25.866167 | IO5: 25.920162 | IP5: 25.966939 | IQ5: 26.006496 | IR5: 17.700156 | IS5: 18.173129 | IT5: 18.622537 | IU5: 19.048375 | IV5: 19.450645 | IW5: 19.829348 | IX5: 20.216349 | IY5: 20.529133 | IZ5: 20.742799 | JA5: 21.064791 | JB5: 21.242471 | JC5: 21.37967 | JD5: 21.557073 | JE5: 21.658955 | JF5: 21.73452 | JG5: 21.755758 | JH5: 22.005873 | JI5: 22.187399 | JJ5: 22.288851 | JK5: 22.538535 | JL5: 22.705717 | JM5: 22.800633 | JN5: 22.964188 | JO5: 23.064703 | JP5: 23.095223 | JQ5: 23.211108 | JR5: 23.45446 | JS5: 23.606903 | JT5: 23.666749 | JU5: 23.829183 | JV5: 23.91266 | JW5: 23.918969 | JX5: 23.957639 | JY5: 23.911342 | JZ5: 23.806462 | KA5: 23.764877 | KB5: 23.610689 | KC5: 23.471531 | KD5: 23.189943 | KE5: 23.086444 | KF5: 22.933678 | KG5: 22.89859 | KH5: 22.810123 | KI5: 22.746361 | KJ5: 22.665259 | KK5: 22.698347 | KL5: 22.550751 | KM5: 22.428819 | KN5: 22.187731 | KO5: 22.058739 | KP5: 21.889035 | KQ5: 21.76024 | KR5: 21.546243 | KS5: 21.353597 | KT5: 21.114028 | KU5: 20.868681 | KV5: 20.606878 | KW5: 20.328622 | KX5: 20.033906 | KY5: 19.722737 | KZ5: 16.119414 | LA5: 16.525879 | LB5: 16.840138 | LC5: 17.062189 | LD5: 17.192038 | LE5: 17.229678 | LF5: 16.735002 | LG5: 16.187243 | LH5: 16.646256 | LI5: 16.589653 | LJ5: 16.665864 | LK5: 16.7469 | LL5: 16.77634 | LM5: 16.798286 | LN5: 16.797843 | LO5: 16.7916 | LP5: 16.793994 | LQ5: 16.843331 | LR5: 16.819765 | LS5: 16.826312 | LT5: 16.842844 | LU5: 16.92344 | LV5: 16.972263 | LW5: 17.064652 | LX5: 17.109323 | LY5: 17.164389 | LZ5: 17.248233 | MA5: 17.287892 | MB5: 17.327527 | MC5: 17.34288 | MD5: 17.332714 | ME5: 17.363734 | MF5: 17.396532 | MG5: 17.521138 | MH5: 17.753734 | MI5: 18.047642 | MJ5: 18.296076 | MK5: 18.465126 | ML5: 18.558699 | MM5: 18.563003 | MN5: 18.508725 | MO5: 18.402195 | MP5: 18.307512 | MQ5: 18.322641 | MR5: 18.36921 | MS5: 18.344564 | MT5: 18.161207 | MU5: 17.875193 | MV5: 17.58762 | MW5: 17.297612 | MX5: 17.018369 | MY5: 16.750296 | MZ5: 16.54144 | NA5: 16.419611 | NB5: 16.244916 | NC5: 16.065122 | ND5: 15.887645 | NE5: 15.670317 | NF5: 15.541479 | NG5: 15.427968 | NH5: 15.373337 | NI5: 15.310523 | NJ5: 15.321022 | NK5: 15.349971 | NL5: 15.262574 | NM5: 15.338835 | NN5: 15.448472 | NO5: 15.492042 | NP5: 15.548315 | NQ5: 15.641478 | NR5: 15.653469 | NS5: 15.643154 | NT5: 15.610534 | NU5: 15.555607 | NV5: 15.478377
A6: 4 | B6: H-306_NEG | C6: 0.8335048 | D6: 0.96879734 | E6: 1.0765011 | F6: 1.1566163 | G6: 1.2091426 | H6: 1.2340803 | I6: 1.1515128 | J6: 1.1133948 | K6: 1.1380192 | L6: 1.1829029 | M6: 1.259044 | N6: 1.3601365 | O6: 1.4844945 | P6: 1.6419557 | Q6: 1.8453322 | R6: 1.7555558 | S6: 1.7691673 | T6: 1.7874087 | U6: 1.8011557 | V6: 1.8262496 | W6: 1.8658685 | X6: 1.8907745 | Y6: 1.9393765 | Z6: 1.9927136 | AA6: 2.043556 | AB6: 2.0883483 | AC6: 2.1414268 | AD6: 2.2028751 | AE6: 2.2728522 | AF6: 2.3719873 | AG6: 2.4880416 | AH6: 2.6226953 | AI6: 2.8183012 | AJ6: 3.0166149 | AK6: 3.2331575 | AL6: 3.4811298 | AM6: 3.7547249 | AN6: 4.0377548 | AO6: 4.3186099 | AP6: 4.5869026 | AQ6: 4.8190256 | AR6: 5.0249499 | AS6: 5.1907825 | AT6: 5.3218716 | AU6: 5.4510602 | AV6: 5.5612644 | AW6: 5.6313659 | AX6: 5.7087109 | AY6: 5.7506386 | AZ6: 5.7680639 | BA6: 5.7365048 | BB6: 5.6544175 | BC6: 5.5615268 | BD6: 5.5332269 | BE6: 5.5004671 | BF6: 5.4591597 | BG6: 5.417607 | BH6: 5.4076036 | BI6: 5.3859562 | BJ6: 5.3849227 | BK6: 5.3708679 | BL6: 5.3717782 | BM6: 5.3785878 | BN6: 5.3975034 | BO6: 5.3883564 | BP6: 5.3824359 | BQ6: 5.3632779 | BR6: 5.3367451 | BS6: 5.3042438 | BT6: 5.2953651 | BU6: 5.2839126 | BV6: 5.3041113 | BW6: 5.2779102 | BX6: 5.2226376 | BY6: 5.2077904 | BZ6: 5.1411846 | CA6: 5.048902 | CB6: 4.952241 | CC6: 4.8560717 | CD6: 4.7811791 | CE6: 4.7171433 | CF6: 4.6819599 | CG6: 4.6123454 | CH6: 4.5824928 | CI6: 4.711368 | CJ6: 4.7828516 | CK6: 4.8753804 | CL6: 5.0296671 | CM6: 5.3526609 | CN6: 5.8175157 | CO6: 6.4192476 | CP6: 7.1485037 | CQ6: 7.9072368 | CR6: 8.8720618 | CS6: 10.092069 | CT6: 11.058966 | CU6: 11.990795 | CV6: 12.876372 | CW6: 13.671172 | CX6: 14.342607 | CY6: 14.931416 | CZ6: 15.426036 | DA6: 15.823176 | DB6: 16.318618 | DC6: 16.844355 | DD6: 17.189438 | DE6: 17.408346 | DF6: 17.642469 | DG6: 18.071911 | DH6: 18.479825 | DI6: 18.795547 | DJ6: 19.02608 | DK6: 19.196253 | DL6: 19.34447 | DM6: 19.418203 | DN6: 19.42038 | DO6: 19.26339 | DP6: 19.307157 | DQ6: 19.580262 | DR6: 19.733986 | DS6: 19.833244 | DT6: 19.931736 | DU6: 20.020832 | DV6: 20.077425 | DW6: 20.147264 | DX6: 20.299718 | DY6: 20.42001 | DZ6: 20.629927 | EA6: 20.824918 | EB6: 20.980061 | EC6: 21.125965 | ED6: 21.234494 | EE6: 21.315771 | EF6: 21.377483 | EG6: 21.485982 | EH6: 21.653959 | EI6: 21.73733 | EJ6: 21.948438 | EK6: 22.078195 | EL6: 22.135669 | EM6: 22.219321 | EN6: 22.358567 | EO6: 22.451748 | EP6: 22.561236 | EQ6: 22.6575 | ER6: 22.7782 | ES6: 22.87587 | ET6: 23.051552 | EU6: 23.16216 | EV6: 23.215554 | EW6: 23.251816 | EX6: 23.442714 | EY6: 23.560735 | EZ6: 23.64001 | FA6: 23.804299 | FB6: 23.965662 | FC6: 24.15438 | FD6: 24.329243 | FE6: 24.480068 | FF6: 24.548492 | FG6: 24.389643 | FH6: 24.280452 | FI6: 24.413663 | FJ6: 24.73892 | FK6: 24.9209 | FL6: 25.186437 | FM6: 25.738071 | FN6: 25.648585 | FO6: 25.52892 | FP6: 25.770678 | FQ6: 24.876031 | FR6: 24.109552 | FS6: 24.225112 | FT6: 23.639188 | FU6: 23.388115 | FV6: 23.152364 | FW6: 23.364662 | FX6: 23.47803 | FY6: 23.575401 | FZ6: 24.087306 | GA6: 24.049599 | GB6: 24.134958 | GC6: 24.760622 | GD6: 24.280007 | GE6: 24.501024 | GF6: 24.533699 | GG6: 24.69587 | GH6: 24.966423 | GI6: 25.014411 | GJ6: 25.117599 | GK6: 25.622473 | GL6: 25.577982 | GM6: 25.643471 | GN6: 25.243188 | GO6: 25.132947 | GP6: 25.253563 | GQ6: 25.310374 | GR6: 25.688726 | GS6: 26.176814 | GT6: 26.310136 | GU6: 26.659862 | GV6: 26.675267 | GW6: 26.636085 | GX6: 26.712033 | GY6: 27.0431 | GZ6: 27.60741 | HA6: 28.243584 | HB6: 28.714732 | HC6: 28.946617 | HD6: 28.862768 | HE6: 28.686729 | HF6: 28.513832 | HG6: 28.545346 | HH6: 28.549562 | HI6: 28.776318 | HJ6: 28.646168 | HK6: 28.594986 | HL6: 28.071284 | HM6: 27.455452 | HN6: 26.811061 | HO6: 26.3248 | HP6: 26.000567 | HQ6: 25.931126 | HR6: 25.98089 | HS6: 26.316422 | HT6: 26.430151 | HU6: 26.73785 | HV6: 26.652843 | HW6: 26.598033 | HX6: 26.453105 | HY6: 26.314482 | HZ6: 26.240199 | IA6: 26.328033 | IB6: 26.595824 | IC6: 26.966321 | ID6: 27.343709 | IE6: 27.687082 | IF6: 27.982196 | IG6: 28.183488 | IH6: 28.250581 | II6: 28.396678 | IJ6: 28.494266 | IK6: 28.58874 | IL6: 28.668913 | IM6: 28.71659 | IN6: 28.744592 | IO6: 28.752921 | IP6: 28.741576 | IQ6: 28.710557 | IR6: 16.150418 | IS6: 16.641427 | IT6: 17.110968 | IU6: 17.559042 | IV6: 17.985649 | IW6: 18.39079 | IX6: 18.798393 | IY6: 19.133736 | IZ6: 19.391979 | JA6: 19.7634 | JB6: 20.006281 | JC6: 20.189112 | JD6: 20.396967 | JE6: 20.546075 | JF6: 20.672768 | JG6: 20.743648 | JH6: 21.039613 | JI6: 21.291909 | JJ6: 21.446816 | JK6: 21.723767 | JL6: 21.934806 | JM6: 22.040054 | JN6: 22.233234 | JO6: 22.359733 | JP6: 22.407493 | JQ6: 22.537649 | JR6: 22.800015 | JS6: 22.962928 | JT6: 23.027162 | JU6: 23.180815 | JV6: 23.263478 | JW6: 23.26695 | JX6: 23.293991 | JY6: 23.223268 | JZ6: 23.108815 | KA6: 23.023886 | KB6: 22.830788 | KC6: 22.650871 | KD6: 22.342813 | KE6: 22.194547 | KF6: 22.022064 | KG6: 21.9541 | KH6: 21.814412 | KI6: 21.720206 | KJ6: 21.623032 | KK6: 21.569382 | KL6: 21.402045 | KM6: 21.244443 | KN6: 20.958906 | KO6: 20.785408 | KP6: 20.582852 | KQ6: 20.397133 | KR6: 20.136172 | KS6: 19.90536 | KT6: 19.625878 | KU6: 19.345335 | KV6: 19.050856 | KW6: 18.742447 | KX6: 18.420104 | KY6: 18.083826 | KZ6: 12.698044 | LA6: 13.037666 | LB6: 13.317928 | LC6: 13.53883 | LD6: 13.70037 | LE6: 13.802553 | LF6: 13.574943 | LG6: 13.52082 | LH6: 13.633739 | LI6: 13.642514 | LJ6: 13.795442 | LK6: 13.890988 | LL6: 13.941382 | LM6: 13.963803 | LN6: 13.969565 | LO6: 13.963913 | LP6: 13.963902 | LQ6: 14.034631 | LR6: 14.014626 | LS6: 14.046156 | LT6: 14.083884 | LU6: 14.167438 | LV6: 14.227086 | LW6: 14.333558 | LX6: 14.39535 | LY6: 14.474868 | LZ6: 14.55484 | MA6: 14.612549 | MB6: 14.661398 | MC6: 14.704317 | MD6: 14.720015 | ME6: 14.768966 | MF6: 14.816036 | MG6: 14.934806 | MH6: 15.160287 | MI6: 15.453611 | MJ6: 15.6623 | MK6: 15.827303 | ML6: 15.94311 | MM6: 15.985335 | MN6: 15.954113 | MO6: 15.881097 | MP6: 15.791376 | MQ6: 15.740798 | MR6: 15.770516 | MS6: 15.743057 | MT6: 15.55324 | MU6: 15.294594 | MV6: 15.01213 | MW6: 14.721529 | MX6: 14.421153 | MY6: 14.15929 | MZ6: 13.95687 | NA6: 13.754367 | NB6: 13.559756 | NC6: 13.393118 | ND6: 13.223683 | NE6: 13.044749 | NF6: 12.887558 | NG6: 12.785105 | NH6: 12.70772 | NI6: 12.697415 | NJ6: 12.692066 | NK6: 12.643546 | NL6: 12.507024 | NM6: 12.57373 | NN6: 12.661298 | NO6: 12.720457 | NP6: 12.773103 | NQ6: 12.837019 | NR6: 12.810657 | NS6: 12.749154 | NT6: 12.652508 | NU6: 12.520722 | NV6: 12.353792
A7: 5 | B7: H-312_NEG | C7: 0.92895189 | D7: 1.0119517 | E7: 1.0900755 | F7: 1.1633231 | G7: 1.2316944 | H7: 1.2951896 | I7: 1.3359744 | J7: 1.3856024 | K7: 1.4534142 | L7: 1.5187837 | M7: 1.5768569 | N7: 1.6292942 | O7: 1.6646672 | P7: 1.7039373 | Q7: 1.7552579 | R7: 1.789803 | S7: 1.8066014 | T7: 1.8273156 | U7: 1.8388636 | V7: 1.8636827 | W7: 1.9022239 | X7: 1.9280113 | Y7: 1.9742683 | Z7: 2.0350852 | AA7: 2.0896282 | AB7: 2.1380729 | AC7: 2.1969641 | AD7: 2.2632649 | AE7: 2.3307354 | AF7: 2.428929 | AG7: 2.5411699 | AH7: 2.672558 | AI7: 2.8684887 | AJ7: 3.0651728 | AK7: 3.2783175 | AL7: 3.5182684 | AM7: 3.7860279 | AN7: 4.0583424 | AO7: 4.3255277 | AP7: 4.583644 | AQ7: 4.8041881 | AR7: 5.0054699 | AS7: 5.1651367 | AT7: 5.2894359 | AU7: 5.4200994 | AV7: 5.5299017 | AW7: 5.6065524 | AX7: 5.6848189 | AY7: 5.7333008 | AZ7: 5.7617742 | BA7: 5.7421797 | BB7: 5.6762129 | BC7: 5.594397 | BD7: 5.5797591 | BE7: 5.5660223 | BF7: 5.539801 | BG7: 5.5107844 | BH7: 5.5064819 | BI7: 5.4945007 | BJ7: 5.5025535 | BK7: 5.4940946 | BL7: 5.5018987 | BM7: 5.5102683 | BN7: 5.5313232 | BO7: 5.5296592 | BP7: 5.5319314 | BQ7: 5.5186557 | BR7: 5.4992642 | BS7: 5.4764193 | BT7: 5.475086 | BU7: 5.4682195 | BV7: 5.4936845 | BW7: 5.4684626 | BX7: 5.4175937 | BY7: 5.4092407 | BZ7: 5.3493658 | CA7: 5.2612504 | CB7: 5.1705433 | CC7: 5.0783886 | CD7: 5.0082026 | CE7: 4.9520996 | CF7: 4.9204013 | CG7: 4.8552451 | CH7: 4.8316123 | CI7: 4.9648221 | CJ7: 5.0415932 | CK7: 5.1364175 | CL7: 5.3002453 | CM7: 5.6290078 | CN7: 6.0958685 | CO7: 6.6861028 | CP7: 7.3856534 | CQ7: 8.105188 | CR7: 9.0124273 | CS7: 10.173921 | CT7: 11.067369 | CU7: 11.921025 | CV7: 12.731763 | CW7: 13.448571 | CX7: 14.027774 | CY7: 14.529974 | CZ7: 14.944095 | DA7: 15.258014 | DB7: 15.67939 | DC7: 16.15332 | DD7: 16.460764 | DE7: 16.63055 | DF7: 16.817012 | DG7: 17.250607 | DH7: 17.661235 | DI7: 17.987964 | DJ7: 18.213676 | DK7: 18.383203 | DL7: 18.529363 | DM7: 18.595628 | DN7: 18.58997 | DO7: 18.390791 | DP7: 18.402581 | DQ7: 18.68038 | DR7: 18.839211 | DS7: 18.937995 | DT7: 19.041198 | DU7: 19.147756 | DV7: 19.209335 | DW7: 19.266069 | DX7: 19.414018 | DY7: 19.504612 | DZ7: 19.695765 | EA7: 19.872543 | EB7: 20.033745 | EC7: 20.182786 | ED7: 20.308791 | EE7: 20.407315 | EF7: 20.477601 | EG7: 20.566211 | EH7: 20.731838 | EI7: 20.784235 | EJ7: 20.985862 | EK7: 21.109351 | EL7: 21.175786 | EM7: 21.262112 | EN7: 21.411987 | EO7: 21.507764 | EP7: 21.620124 | EQ7: 21.708554 | ER7: 21.827803 | ES7: 21.902748 | ET7: 22.08034 | EU7: 22.177925 | EV7: 22.209981 | EW7: 22.222297 | EX7: 22.416972 | EY7: 22.537418 | EZ7: 22.604417 | FA7: 22.786319 | FB7: 22.941537 | FC7: 23.152184 | FD7: 23.352246 | FE7: 23.504288 | FF7: 23.571067 | FG7: 23.382986 | FH7: 23.2265 | FI7: 23.367725 | FJ7: 23.73554 | FK7: 23.947718 | FL7: 24.241371 | FM7: 24.873917 | FN7: 24.782018 | FO7: 24.686679 | FP7: 24.912234 | FQ7: 23.98267 | FR7: 23.213565 | FS7: 23.357005 | FT7: 22.873728 | FU7: 22.657795 | FV7: 22.5159 | FW7: 22.798912 | FX7: 22.866025 | FY7: 22.965765 | FZ7: 23.423149 | GA7: 23.352259 | GB7: 23.414446 | GC7: 23.974117 | GD7: 23.531627 | GE7: 23.774285 | GF7: 23.81665 | GG7: 23.991886 | GH7: 24.244383 | GI7: 24.265379 | GJ7: 24.333514 | GK7: 24.788337 | GL7: 24.693466 | GM7: 24.726935 | GN7: 24.346285 | GO7: 24.278052 | GP7: 24.421342 | GQ7: 24.516404 | GR7: 24.885982 | GS7: 25.317995 | GT7: 25.414522 | GU7: 25.699916 | GV7: 25.667045 | GW7: 25.62761 | GX7: 25.715714 | GY7: 26.080056 | GZ7: 26.651944 | HA7: 27.239571 | HB7: 27.656838 | HC7: 27.835276 | HD7: 27.731463 | HE7: 27.566062 | HF7: 27.450937 | HG7: 27.520304 | HH7: 27.524268 | HI7: 27.780027 | HJ7: 27.642518 | HK7: 27.637331 | HL7: 27.157222 | HM7: 26.604142 | HN7: 26.079634 | HO7: 25.734854 | HP7: 25.556441 | HQ7: 25.545406 | HR7: 25.619562 | HS7: 25.969949 | HT7: 26.057617 | HU7: 26.378877 | HV7: 26.242274 | HW7: 26.149509 | HX7: 26.023659 | HY7: 25.909881 | HZ7: 25.868426 | IA7: 25.969682 | IB7: 26.245401 | IC7: 26.616997 | ID7: 26.990825 | IE7: 27.333896 | IF7: 27.601116 | IG7: 27.764617 | IH7: 27.820577 | II7: 27.937997 | IJ7: 28.028795 | IK7: 28.134268 | IL7: 28.228112 | IM7: 28.296211 | IN7: 28.353607 | IO7: 28.400302 | IP7: 28.436297 | IQ7: 28.46159 | IR7: 17.197312 | IS7: 17.704682 | IT7: 18.188374 | IU7: 18.648393 | IV7: 19.084735 | IW7: 19.497403 | IX7: 19.908507 | IY7: 20.264009 | IZ7: 20.502734 | JA7: 20.882673 | JB7: 21.098466 | JC7: 21.264673 | JD7: 21.47207 | JE7: 21.577381 | JF7: 21.694207 | JG7: 21.723553 | JH7: 22.003582 | JI7: 22.217516 | JJ7: 22.329343 | JK7: 22.625732 | JL7: 22.805844 | JM7: 22.929084 | JN7: 23.136188 | JO7: 23.250732 | JP7: 23.325835 | JQ7: 23.443739 | JR7: 23.702115 | JS7: 23.858627 | JT7: 23.905675 | JU7: 24.058039 | JV7: 24.133303 | JW7: 24.133634 | JX7: 24.174321 | JY7: 24.112309 | JZ7: 24.00016 | KA7: 23.911381 | KB7: 23.719531 | KC7: 23.546058 | KD7: 23.218497 | KE7: 23.077888 | KF7: 22.910931 | KG7: 22.843861 | KH7: 22.736523 | KI7: 22.654428 | KJ7: 22.541886 | KK7: 22.525213 | KL7: 22.363519 | KM7: 22.211037 | KN7: 21.943386 | KO7: 21.792707 | KP7: 21.597097 | KQ7: 21.439 | KR7: 21.198469 | KS7: 20.973398 | KT7: 20.698122 | KU7: 20.424538 | KV7: 20.13669 | KW7: 19.834579 | KX7: 19.518204 | KY7: 19.187567 | KZ7: 14.047963 | LA7: 14.45352 | LB7: 14.785332 | LC7: 15.043396 | LD7: 15.227717 | LE7: 15.338292 | LF7: 15.102781 | LG7: 14.990687 | LH7: 15.097776 | LI7: 15.084553 | LJ7: 15.206525 | LK7: 15.32239 | LL7: 15.376252 | LM7: 15.393029 | LN7: 15.388403 | LO7: 15.369132 | LP7: 15.34943 | LQ7: 15.394427 | LR7: 15.364597 | LS7: 15.378581 | LT7: 15.399321 | LU7: 15.486464 | LV7: 15.540274 | LW7: 15.640379 | LX7: 15.700695 | LY7: 15.775475 | LZ7: 15.855128 | MA7: 15.882856 | MB7: 15.930808 | MC7: 15.960316 | MD7: 15.974204 | ME7: 16.004229 | MF7: 16.025891 | MG7: 16.174209 | MH7: 16.401792 | MI7: 16.701025 | MJ7: 16.92671 | MK7: 17.09844 | ML7: 17.244222 | MM7: 17.249529 | MN7: 17.219575 | MO7: 17.112638 | MP7: 17.025266 | MQ7: 17.027436 | MR7: 17.06484 | MS7: 17.05619 | MT7: 16.871248 | MU7: 16.590228 | MV7: 16.293228 | MW7: 15.940685 | MX7: 15.666018 | MY7: 15.350286 | MZ7: 15.116808 | NA7: 14.942437 | NB7: 14.773351 | NC7: 14.606785 | ND7: 14.416454 | NE7: 14.204095 | NF7: 14.068925 | NG7: 13.986264 | NH7: 13.922613 | NI7: 13.879938 | NJ7: 13.853893 | NK7: 13.850767 | NL7: 13.706159 | NM7: 13.787047 | NN7: 13.917732 | NO7: 13.981461 | NP7: 14.086264 | NQ7: 14.158818 | NR7: 14.15526 | NS7: 14.114395 | NT7: 14.036223 | NU7: 13.920743 | NV7: 13.767953
